2016-11-29 15:34:12,008 Exception on /get_stims [GET]
Traceback (most recent call last):
  File "/Users/zorba/anaconda2/lib/python2.7/site-packages/flask/app.py", line 1817, in wsgi_app
    response = self.full_dispatch_request()
  File "/Users/zorba/anaconda2/lib/python2.7/site-packages/flask/app.py", line 1477, in full_dispatch_request
    rv = self.handle_user_exception(e)
  File "/Users/zorba/anaconda2/lib/python2.7/site-packages/flask/app.py", line 1381, in handle_user_exception
    reraise(exc_type, exc_value, tb)
  File "/Users/zorba/anaconda2/lib/python2.7/site-packages/flask/app.py", line 1475, in full_dispatch_request
    rv = self.dispatch_request()
  File "/Users/zorba/anaconda2/lib/python2.7/site-packages/flask/app.py", line 1461, in dispatch_request
    return self.view_functions[rule.endpoint](**req.view_args)
  File "/Users/zorba/Dropbox/Neuro/psiturk/Swaps-no-fix/custom.py", line 131, in get_stims
    print load_from_db(params)
  File "/Users/zorba/Dropbox/Neuro/psiturk/Swaps-no-fix/custom.py", line 153, in load_from_db
    assert params["n_trials"]< len(all_trials)+1
AssertionError
2016-11-29 15:34:31,251 Exception on /get_stims [GET]
Traceback (most recent call last):
  File "/Users/zorba/anaconda2/lib/python2.7/site-packages/flask/app.py", line 1817, in wsgi_app
    response = self.full_dispatch_request()
  File "/Users/zorba/anaconda2/lib/python2.7/site-packages/flask/app.py", line 1477, in full_dispatch_request
    rv = self.handle_user_exception(e)
  File "/Users/zorba/anaconda2/lib/python2.7/site-packages/flask/app.py", line 1381, in handle_user_exception
    reraise(exc_type, exc_value, tb)
  File "/Users/zorba/anaconda2/lib/python2.7/site-packages/flask/app.py", line 1475, in full_dispatch_request
    rv = self.dispatch_request()
  File "/Users/zorba/anaconda2/lib/python2.7/site-packages/flask/app.py", line 1461, in dispatch_request
    return self.view_functions[rule.endpoint](**req.view_args)
  File "/Users/zorba/Dropbox/Neuro/psiturk/Swaps-no-fix/custom.py", line 131, in get_stims
    load_from_db(params)
  File "/Users/zorba/Dropbox/Neuro/psiturk/Swaps-no-fix/custom.py", line 153, in load_from_db
    def load_from_db(params):
AssertionError
2016-11-29 15:34:54,846 Exception on /get_stims [GET]
Traceback (most recent call last):
  File "/Users/zorba/anaconda2/lib/python2.7/site-packages/flask/app.py", line 1817, in wsgi_app
    response = self.full_dispatch_request()
  File "/Users/zorba/anaconda2/lib/python2.7/site-packages/flask/app.py", line 1477, in full_dispatch_request
    rv = self.handle_user_exception(e)
  File "/Users/zorba/anaconda2/lib/python2.7/site-packages/flask/app.py", line 1381, in handle_user_exception
    reraise(exc_type, exc_value, tb)
  File "/Users/zorba/anaconda2/lib/python2.7/site-packages/flask/app.py", line 1475, in full_dispatch_request
    rv = self.dispatch_request()
  File "/Users/zorba/anaconda2/lib/python2.7/site-packages/flask/app.py", line 1461, in dispatch_request
    return self.view_functions[rule.endpoint](**req.view_args)
  File "/Users/zorba/Dropbox/Neuro/psiturk/Swaps-no-fix/custom.py", line 131, in get_stims
    load_from_db(params)
  File "/Users/zorba/Dropbox/Neuro/psiturk/Swaps-no-fix/custom.py", line 155, in load_from_db
    assert params["n_trials"]< len(all_trials)+1
AssertionError
2016-11-29 15:34:54,851 Exception on /get_stims [GET]
Traceback (most recent call last):
  File "/Users/zorba/anaconda2/lib/python2.7/site-packages/flask/app.py", line 1817, in wsgi_app
    response = self.full_dispatch_request()
  File "/Users/zorba/anaconda2/lib/python2.7/site-packages/flask/app.py", line 1478, in full_dispatch_request
    response = self.make_response(rv)
  File "/Users/zorba/anaconda2/lib/python2.7/site-packages/flask/app.py", line 1566, in make_response
    raise ValueError('View function did not return a response')
ValueError: View function did not return a response
2016-11-29 15:34:59,826 Exception on /get_stims [GET]
Traceback (most recent call last):
  File "/Users/zorba/anaconda2/lib/python2.7/site-packages/flask/app.py", line 1817, in wsgi_app
    response = self.full_dispatch_request()
  File "/Users/zorba/anaconda2/lib/python2.7/site-packages/flask/app.py", line 1478, in full_dispatch_request
    response = self.make_response(rv)
  File "/Users/zorba/anaconda2/lib/python2.7/site-packages/flask/app.py", line 1566, in make_response
    raise ValueError('View function did not return a response')
ValueError: View function did not return a response
[2016-11-29 19:01:32 -0500] [27754] [CRITICAL] WORKER TIMEOUT (pid:27758)
[2016-11-29 19:01:32 -0500] [27754] [CRITICAL] WORKER TIMEOUT (pid:27759)
[2016-11-29 19:01:32 -0500] [27754] [CRITICAL] WORKER TIMEOUT (pid:27760)
[2016-11-29 19:01:32 -0500] [27754] [CRITICAL] WORKER TIMEOUT (pid:27761)
[2016-11-29 19:01:32 -0500] [27754] [CRITICAL] WORKER TIMEOUT (pid:27762)
[2016-11-29 19:01:32 -0500] [27754] [CRITICAL] WORKER TIMEOUT (pid:27763)
[2016-11-29 19:01:32 -0500] [27754] [CRITICAL] WORKER TIMEOUT (pid:27764)
[2016-11-29 19:01:32 -0500] [27754] [CRITICAL] WORKER TIMEOUT (pid:27765)
[2016-11-29 19:01:32 -0500] [27754] [CRITICAL] WORKER TIMEOUT (pid:27766)
2016-11-29 19:10:05,504 error_setting_worker_complete (1017) {'uniqueId': [u'debugEcHRT:debugUwRXc']}
2016-11-29 19:10:11,522 Exception on /ad [GET]
Traceback (most recent call last):
  File "/Users/zorba/anaconda2/lib/python2.7/site-packages/flask/app.py", line 1817, in wsgi_app
    response = self.full_dispatch_request()
  File "/Users/zorba/anaconda2/lib/python2.7/site-packages/flask/app.py", line 1477, in full_dispatch_request
    rv = self.handle_user_exception(e)
  File "/Users/zorba/anaconda2/lib/python2.7/site-packages/flask/app.py", line 1381, in handle_user_exception
    reraise(exc_type, exc_value, tb)
  File "/Users/zorba/anaconda2/lib/python2.7/site-packages/flask/app.py", line 1475, in full_dispatch_request
    rv = self.dispatch_request()
  File "/Users/zorba/anaconda2/lib/python2.7/site-packages/flask/app.py", line 1461, in dispatch_request
    return self.view_functions[rule.endpoint](**req.view_args)
  File "/Users/zorba/anaconda2/lib/python2.7/site-packages/psiturk/user_utils.py", line 20, in new_func
    resp = make_response(func(*args, **kwargs))
  File "/Users/zorba/anaconda2/lib/python2.7/site-packages/psiturk/experiment.py", line 249, in advertisement
    filter(Participant.workerid == worker_id).\
  File "/Users/zorba/anaconda2/lib/python2.7/site-packages/sqlalchemy/orm/query.py", line 2535, in count
    return self.from_self(col).scalar()
  File "/Users/zorba/anaconda2/lib/python2.7/site-packages/sqlalchemy/orm/query.py", line 2341, in scalar
    ret = self.one()
  File "/Users/zorba/anaconda2/lib/python2.7/site-packages/sqlalchemy/orm/query.py", line 2310, in one
    ret = list(self)
  File "/Users/zorba/anaconda2/lib/python2.7/site-packages/sqlalchemy/orm/query.py", line 2353, in __iter__
    return self._execute_and_instances(context)
  File "/Users/zorba/anaconda2/lib/python2.7/site-packages/sqlalchemy/orm/query.py", line 2368, in _execute_and_instances
    result = conn.execute(querycontext.statement, self._params)
  File "/Users/zorba/anaconda2/lib/python2.7/site-packages/sqlalchemy/engine/base.py", line 662, in execute
    params)
  File "/Users/zorba/anaconda2/lib/python2.7/site-packages/sqlalchemy/engine/base.py", line 761, in _execute_clauseelement
    compiled_sql, distilled_params
  File "/Users/zorba/anaconda2/lib/python2.7/site-packages/sqlalchemy/engine/base.py", line 874, in _execute_context
    context)
  File "/Users/zorba/anaconda2/lib/python2.7/site-packages/sqlalchemy/engine/base.py", line 1024, in _handle_dbapi_exception
    exc_info
  File "/Users/zorba/anaconda2/lib/python2.7/site-packages/sqlalchemy/util/compat.py", line 196, in raise_from_cause
    reraise(type(exception), exception, tb=exc_tb)
  File "/Users/zorba/anaconda2/lib/python2.7/site-packages/sqlalchemy/engine/base.py", line 867, in _execute_context
    context)
  File "/Users/zorba/anaconda2/lib/python2.7/site-packages/sqlalchemy/engine/default.py", line 324, in do_execute
    cursor.execute(statement, parameters)
OperationalError: (OperationalError) no such table: swaps u'SELECT count(*) AS count_1 \nFROM (SELECT swaps.uniqueid AS swaps_uniqueid, swaps.assignmentid AS swaps_assignmentid, swaps.workerid AS swaps_workerid, swaps.hitid AS swaps_hitid, swaps.ipaddress AS swaps_ipaddress, swaps.browser AS swaps_browser, swaps.platform AS swaps_platform, swaps.language AS swaps_language, swaps.cond AS swaps_cond, swaps.counterbalance AS swaps_counterbalance, swaps.codeversion AS swaps_codeversion, swaps.beginhit AS swaps_beginhit, swaps.beginexp AS swaps_beginexp, swaps.endhit AS swaps_endhit, swaps.bonus AS swaps_bonus, swaps.status AS swaps_status, swaps.datastring AS swaps_datastring \nFROM swaps \nWHERE swaps.assignmentid != ? AND swaps.workerid = ?) AS anon_1' (u'debugTCIBz', u'debugoHv5Y')
2016-11-29 19:27:47,988 Exception on /ad [GET]
Traceback (most recent call last):
  File "/Users/zorba/anaconda2/lib/python2.7/site-packages/flask/app.py", line 1817, in wsgi_app
    response = self.full_dispatch_request()
  File "/Users/zorba/anaconda2/lib/python2.7/site-packages/flask/app.py", line 1477, in full_dispatch_request
    rv = self.handle_user_exception(e)
  File "/Users/zorba/anaconda2/lib/python2.7/site-packages/flask/app.py", line 1381, in handle_user_exception
    reraise(exc_type, exc_value, tb)
  File "/Users/zorba/anaconda2/lib/python2.7/site-packages/flask/app.py", line 1475, in full_dispatch_request
    rv = self.dispatch_request()
  File "/Users/zorba/anaconda2/lib/python2.7/site-packages/flask/app.py", line 1461, in dispatch_request
    return self.view_functions[rule.endpoint](**req.view_args)
  File "/Users/zorba/anaconda2/lib/python2.7/site-packages/psiturk/user_utils.py", line 20, in new_func
    resp = make_response(func(*args, **kwargs))
  File "/Users/zorba/anaconda2/lib/python2.7/site-packages/psiturk/experiment.py", line 249, in advertisement
    filter(Participant.workerid == worker_id).\
  File "/Users/zorba/anaconda2/lib/python2.7/site-packages/sqlalchemy/orm/query.py", line 2535, in count
    return self.from_self(col).scalar()
  File "/Users/zorba/anaconda2/lib/python2.7/site-packages/sqlalchemy/orm/query.py", line 2341, in scalar
    ret = self.one()
  File "/Users/zorba/anaconda2/lib/python2.7/site-packages/sqlalchemy/orm/query.py", line 2310, in one
    ret = list(self)
  File "/Users/zorba/anaconda2/lib/python2.7/site-packages/sqlalchemy/orm/query.py", line 2353, in __iter__
    return self._execute_and_instances(context)
  File "/Users/zorba/anaconda2/lib/python2.7/site-packages/sqlalchemy/orm/query.py", line 2368, in _execute_and_instances
    result = conn.execute(querycontext.statement, self._params)
  File "/Users/zorba/anaconda2/lib/python2.7/site-packages/sqlalchemy/engine/base.py", line 662, in execute
    params)
  File "/Users/zorba/anaconda2/lib/python2.7/site-packages/sqlalchemy/engine/base.py", line 761, in _execute_clauseelement
    compiled_sql, distilled_params
  File "/Users/zorba/anaconda2/lib/python2.7/site-packages/sqlalchemy/engine/base.py", line 874, in _execute_context
    context)
  File "/Users/zorba/anaconda2/lib/python2.7/site-packages/sqlalchemy/engine/base.py", line 1024, in _handle_dbapi_exception
    exc_info
  File "/Users/zorba/anaconda2/lib/python2.7/site-packages/sqlalchemy/util/compat.py", line 196, in raise_from_cause
    reraise(type(exception), exception, tb=exc_tb)
  File "/Users/zorba/anaconda2/lib/python2.7/site-packages/sqlalchemy/engine/base.py", line 867, in _execute_context
    context)
  File "/Users/zorba/anaconda2/lib/python2.7/site-packages/sqlalchemy/engine/default.py", line 324, in do_execute
    cursor.execute(statement, parameters)
OperationalError: (OperationalError) no such table: swaps u'SELECT count(*) AS count_1 \nFROM (SELECT swaps.uniqueid AS swaps_uniqueid, swaps.assignmentid AS swaps_assignmentid, swaps.workerid AS swaps_workerid, swaps.hitid AS swaps_hitid, swaps.ipaddress AS swaps_ipaddress, swaps.browser AS swaps_browser, swaps.platform AS swaps_platform, swaps.language AS swaps_language, swaps.cond AS swaps_cond, swaps.counterbalance AS swaps_counterbalance, swaps.codeversion AS swaps_codeversion, swaps.beginhit AS swaps_beginhit, swaps.beginexp AS swaps_beginexp, swaps.endhit AS swaps_endhit, swaps.bonus AS swaps_bonus, swaps.status AS swaps_status, swaps.datastring AS swaps_datastring \nFROM swaps \nWHERE swaps.assignmentid != ? AND swaps.workerid = ?) AS anon_1' (u'debugohXff', u'debugS5PWy')
2016-11-29 19:28:00,425 Exception on /ad [GET]
Traceback (most recent call last):
  File "/Users/zorba/anaconda2/lib/python2.7/site-packages/flask/app.py", line 1817, in wsgi_app
    response = self.full_dispatch_request()
  File "/Users/zorba/anaconda2/lib/python2.7/site-packages/flask/app.py", line 1477, in full_dispatch_request
    rv = self.handle_user_exception(e)
  File "/Users/zorba/anaconda2/lib/python2.7/site-packages/flask/app.py", line 1381, in handle_user_exception
    reraise(exc_type, exc_value, tb)
  File "/Users/zorba/anaconda2/lib/python2.7/site-packages/flask/app.py", line 1475, in full_dispatch_request
    rv = self.dispatch_request()
  File "/Users/zorba/anaconda2/lib/python2.7/site-packages/flask/app.py", line 1461, in dispatch_request
    return self.view_functions[rule.endpoint](**req.view_args)
  File "/Users/zorba/anaconda2/lib/python2.7/site-packages/psiturk/user_utils.py", line 20, in new_func
    resp = make_response(func(*args, **kwargs))
  File "/Users/zorba/anaconda2/lib/python2.7/site-packages/psiturk/experiment.py", line 249, in advertisement
    filter(Participant.workerid == worker_id).\
  File "/Users/zorba/anaconda2/lib/python2.7/site-packages/sqlalchemy/orm/query.py", line 2535, in count
    return self.from_self(col).scalar()
  File "/Users/zorba/anaconda2/lib/python2.7/site-packages/sqlalchemy/orm/query.py", line 2341, in scalar
    ret = self.one()
  File "/Users/zorba/anaconda2/lib/python2.7/site-packages/sqlalchemy/orm/query.py", line 2310, in one
    ret = list(self)
  File "/Users/zorba/anaconda2/lib/python2.7/site-packages/sqlalchemy/orm/query.py", line 2353, in __iter__
    return self._execute_and_instances(context)
  File "/Users/zorba/anaconda2/lib/python2.7/site-packages/sqlalchemy/orm/query.py", line 2368, in _execute_and_instances
    result = conn.execute(querycontext.statement, self._params)
  File "/Users/zorba/anaconda2/lib/python2.7/site-packages/sqlalchemy/engine/base.py", line 662, in execute
    params)
  File "/Users/zorba/anaconda2/lib/python2.7/site-packages/sqlalchemy/engine/base.py", line 761, in _execute_clauseelement
    compiled_sql, distilled_params
  File "/Users/zorba/anaconda2/lib/python2.7/site-packages/sqlalchemy/engine/base.py", line 874, in _execute_context
    context)
  File "/Users/zorba/anaconda2/lib/python2.7/site-packages/sqlalchemy/engine/base.py", line 1024, in _handle_dbapi_exception
    exc_info
  File "/Users/zorba/anaconda2/lib/python2.7/site-packages/sqlalchemy/util/compat.py", line 196, in raise_from_cause
    reraise(type(exception), exception, tb=exc_tb)
  File "/Users/zorba/anaconda2/lib/python2.7/site-packages/sqlalchemy/engine/base.py", line 867, in _execute_context
    context)
  File "/Users/zorba/anaconda2/lib/python2.7/site-packages/sqlalchemy/engine/default.py", line 324, in do_execute
    cursor.execute(statement, parameters)
OperationalError: (OperationalError) no such table: swaps u'SELECT count(*) AS count_1 \nFROM (SELECT swaps.uniqueid AS swaps_uniqueid, swaps.assignmentid AS swaps_assignmentid, swaps.workerid AS swaps_workerid, swaps.hitid AS swaps_hitid, swaps.ipaddress AS swaps_ipaddress, swaps.browser AS swaps_browser, swaps.platform AS swaps_platform, swaps.language AS swaps_language, swaps.cond AS swaps_cond, swaps.counterbalance AS swaps_counterbalance, swaps.codeversion AS swaps_codeversion, swaps.beginhit AS swaps_beginhit, swaps.beginexp AS swaps_beginexp, swaps.endhit AS swaps_endhit, swaps.bonus AS swaps_bonus, swaps.status AS swaps_status, swaps.datastring AS swaps_datastring \nFROM swaps \nWHERE swaps.assignmentid != ? AND swaps.workerid = ?) AS anon_1' (u'debugohXff', u'debugS5PWy')
2016-11-29 19:28:03,651 Exception on /ad [GET]
Traceback (most recent call last):
  File "/Users/zorba/anaconda2/lib/python2.7/site-packages/flask/app.py", line 1817, in wsgi_app
    response = self.full_dispatch_request()
  File "/Users/zorba/anaconda2/lib/python2.7/site-packages/flask/app.py", line 1477, in full_dispatch_request
    rv = self.handle_user_exception(e)
  File "/Users/zorba/anaconda2/lib/python2.7/site-packages/flask/app.py", line 1381, in handle_user_exception
    reraise(exc_type, exc_value, tb)
  File "/Users/zorba/anaconda2/lib/python2.7/site-packages/flask/app.py", line 1475, in full_dispatch_request
    rv = self.dispatch_request()
  File "/Users/zorba/anaconda2/lib/python2.7/site-packages/flask/app.py", line 1461, in dispatch_request
    return self.view_functions[rule.endpoint](**req.view_args)
  File "/Users/zorba/anaconda2/lib/python2.7/site-packages/psiturk/user_utils.py", line 20, in new_func
    resp = make_response(func(*args, **kwargs))
  File "/Users/zorba/anaconda2/lib/python2.7/site-packages/psiturk/experiment.py", line 249, in advertisement
    filter(Participant.workerid == worker_id).\
  File "/Users/zorba/anaconda2/lib/python2.7/site-packages/sqlalchemy/orm/query.py", line 2535, in count
    return self.from_self(col).scalar()
  File "/Users/zorba/anaconda2/lib/python2.7/site-packages/sqlalchemy/orm/query.py", line 2341, in scalar
    ret = self.one()
  File "/Users/zorba/anaconda2/lib/python2.7/site-packages/sqlalchemy/orm/query.py", line 2310, in one
    ret = list(self)
  File "/Users/zorba/anaconda2/lib/python2.7/site-packages/sqlalchemy/orm/query.py", line 2353, in __iter__
    return self._execute_and_instances(context)
  File "/Users/zorba/anaconda2/lib/python2.7/site-packages/sqlalchemy/orm/query.py", line 2368, in _execute_and_instances
    result = conn.execute(querycontext.statement, self._params)
  File "/Users/zorba/anaconda2/lib/python2.7/site-packages/sqlalchemy/engine/base.py", line 662, in execute
    params)
  File "/Users/zorba/anaconda2/lib/python2.7/site-packages/sqlalchemy/engine/base.py", line 761, in _execute_clauseelement
    compiled_sql, distilled_params
  File "/Users/zorba/anaconda2/lib/python2.7/site-packages/sqlalchemy/engine/base.py", line 874, in _execute_context
    context)
  File "/Users/zorba/anaconda2/lib/python2.7/site-packages/sqlalchemy/engine/base.py", line 1024, in _handle_dbapi_exception
    exc_info
  File "/Users/zorba/anaconda2/lib/python2.7/site-packages/sqlalchemy/util/compat.py", line 196, in raise_from_cause
    reraise(type(exception), exception, tb=exc_tb)
  File "/Users/zorba/anaconda2/lib/python2.7/site-packages/sqlalchemy/engine/base.py", line 867, in _execute_context
    context)
  File "/Users/zorba/anaconda2/lib/python2.7/site-packages/sqlalchemy/engine/default.py", line 324, in do_execute
    cursor.execute(statement, parameters)
OperationalError: (OperationalError) no such table: swaps u'SELECT count(*) AS count_1 \nFROM (SELECT swaps.uniqueid AS swaps_uniqueid, swaps.assignmentid AS swaps_assignmentid, swaps.workerid AS swaps_workerid, swaps.hitid AS swaps_hitid, swaps.ipaddress AS swaps_ipaddress, swaps.browser AS swaps_browser, swaps.platform AS swaps_platform, swaps.language AS swaps_language, swaps.cond AS swaps_cond, swaps.counterbalance AS swaps_counterbalance, swaps.codeversion AS swaps_codeversion, swaps.beginhit AS swaps_beginhit, swaps.beginexp AS swaps_beginexp, swaps.endhit AS swaps_endhit, swaps.bonus AS swaps_bonus, swaps.status AS swaps_status, swaps.datastring AS swaps_datastring \nFROM swaps \nWHERE swaps.assignmentid != ? AND swaps.workerid = ?) AS anon_1' (u'debugtboSa', u'debug4hEtb')
[2016-11-30 01:55:46 -0500] [28200] [CRITICAL] WORKER TIMEOUT (pid:28204)
[2016-11-30 01:55:46 -0500] [28200] [CRITICAL] WORKER TIMEOUT (pid:28205)
[2016-11-30 01:55:46 -0500] [28200] [CRITICAL] WORKER TIMEOUT (pid:28206)
[2016-11-30 01:55:46 -0500] [28200] [CRITICAL] WORKER TIMEOUT (pid:28207)
[2016-11-30 01:55:46 -0500] [28200] [CRITICAL] WORKER TIMEOUT (pid:28208)
[2016-11-30 01:55:46 -0500] [28200] [CRITICAL] WORKER TIMEOUT (pid:28209)
[2016-11-30 01:55:46 -0500] [28200] [CRITICAL] WORKER TIMEOUT (pid:28210)
[2016-11-30 01:55:46 -0500] [28200] [CRITICAL] WORKER TIMEOUT (pid:28211)
[2016-11-30 01:55:46 -0500] [28200] [CRITICAL] WORKER TIMEOUT (pid:28212)
[2016-11-30 10:14:25 -0500] [28200] [CRITICAL] WORKER TIMEOUT (pid:28336)
[2016-11-30 10:14:25 -0500] [28200] [CRITICAL] WORKER TIMEOUT (pid:28335)
[2016-11-30 10:14:25 -0500] [28200] [CRITICAL] WORKER TIMEOUT (pid:28337)
[2016-11-30 10:14:25 -0500] [28200] [CRITICAL] WORKER TIMEOUT (pid:28338)
[2016-11-30 10:14:25 -0500] [28200] [CRITICAL] WORKER TIMEOUT (pid:28339)
[2016-11-30 10:14:25 -0500] [28200] [CRITICAL] WORKER TIMEOUT (pid:28340)
[2016-11-30 10:14:25 -0500] [28200] [CRITICAL] WORKER TIMEOUT (pid:28334)
[2016-11-30 10:14:25 -0500] [28200] [CRITICAL] WORKER TIMEOUT (pid:28342)
[2016-11-30 10:14:25 -0500] [28200] [CRITICAL] WORKER TIMEOUT (pid:28341)
[2016-11-30 10:46:08 -0500] [28200] [CRITICAL] WORKER TIMEOUT (pid:28448)
[2016-11-30 10:46:08 -0500] [28200] [CRITICAL] WORKER TIMEOUT (pid:28449)
[2016-11-30 10:46:08 -0500] [28200] [CRITICAL] WORKER TIMEOUT (pid:28450)
[2016-11-30 10:46:08 -0500] [28200] [CRITICAL] WORKER TIMEOUT (pid:28451)
[2016-11-30 10:46:08 -0500] [28200] [CRITICAL] WORKER TIMEOUT (pid:28452)
[2016-11-30 10:46:08 -0500] [28200] [CRITICAL] WORKER TIMEOUT (pid:28453)
[2016-11-30 10:46:08 -0500] [28200] [CRITICAL] WORKER TIMEOUT (pid:28454)
[2016-11-30 10:46:08 -0500] [28200] [CRITICAL] WORKER TIMEOUT (pid:28455)
[2016-11-30 10:46:08 -0500] [28200] [CRITICAL] WORKER TIMEOUT (pid:28456)
[2016-11-30 11:59:22 -0500] [28200] [CRITICAL] WORKER TIMEOUT (pid:28480)
[2016-11-30 11:59:22 -0500] [28200] [CRITICAL] WORKER TIMEOUT (pid:28481)
[2016-11-30 11:59:22 -0500] [28200] [CRITICAL] WORKER TIMEOUT (pid:28482)
[2016-11-30 11:59:22 -0500] [28200] [CRITICAL] WORKER TIMEOUT (pid:28483)
[2016-11-30 11:59:22 -0500] [28200] [CRITICAL] WORKER TIMEOUT (pid:28484)
[2016-11-30 11:59:22 -0500] [28200] [CRITICAL] WORKER TIMEOUT (pid:28485)
[2016-11-30 11:59:22 -0500] [28200] [CRITICAL] WORKER TIMEOUT (pid:28486)
[2016-11-30 11:59:22 -0500] [28200] [CRITICAL] WORKER TIMEOUT (pid:28487)
[2016-11-30 11:59:22 -0500] [28200] [CRITICAL] WORKER TIMEOUT (pid:28488)
2016-11-30 12:30:21,071 Exception on /ad [GET]
Traceback (most recent call last):
  File "/Users/zorba/anaconda2/lib/python2.7/site-packages/flask/app.py", line 1817, in wsgi_app
    response = self.full_dispatch_request()
  File "/Users/zorba/anaconda2/lib/python2.7/site-packages/flask/app.py", line 1477, in full_dispatch_request
    rv = self.handle_user_exception(e)
  File "/Users/zorba/anaconda2/lib/python2.7/site-packages/flask/app.py", line 1381, in handle_user_exception
    reraise(exc_type, exc_value, tb)
  File "/Users/zorba/anaconda2/lib/python2.7/site-packages/flask/app.py", line 1475, in full_dispatch_request
    rv = self.dispatch_request()
  File "/Users/zorba/anaconda2/lib/python2.7/site-packages/flask/app.py", line 1461, in dispatch_request
    return self.view_functions[rule.endpoint](**req.view_args)
  File "/Users/zorba/anaconda2/lib/python2.7/site-packages/psiturk/user_utils.py", line 20, in new_func
    resp = make_response(func(*args, **kwargs))
  File "/Users/zorba/anaconda2/lib/python2.7/site-packages/psiturk/experiment.py", line 249, in advertisement
    filter(Participant.workerid == worker_id).\
  File "/Users/zorba/anaconda2/lib/python2.7/site-packages/sqlalchemy/orm/query.py", line 2535, in count
    return self.from_self(col).scalar()
  File "/Users/zorba/anaconda2/lib/python2.7/site-packages/sqlalchemy/orm/query.py", line 2341, in scalar
    ret = self.one()
  File "/Users/zorba/anaconda2/lib/python2.7/site-packages/sqlalchemy/orm/query.py", line 2310, in one
    ret = list(self)
  File "/Users/zorba/anaconda2/lib/python2.7/site-packages/sqlalchemy/orm/query.py", line 2353, in __iter__
    return self._execute_and_instances(context)
  File "/Users/zorba/anaconda2/lib/python2.7/site-packages/sqlalchemy/orm/query.py", line 2368, in _execute_and_instances
    result = conn.execute(querycontext.statement, self._params)
  File "/Users/zorba/anaconda2/lib/python2.7/site-packages/sqlalchemy/engine/base.py", line 662, in execute
    params)
  File "/Users/zorba/anaconda2/lib/python2.7/site-packages/sqlalchemy/engine/base.py", line 761, in _execute_clauseelement
    compiled_sql, distilled_params
  File "/Users/zorba/anaconda2/lib/python2.7/site-packages/sqlalchemy/engine/base.py", line 874, in _execute_context
    context)
  File "/Users/zorba/anaconda2/lib/python2.7/site-packages/sqlalchemy/engine/base.py", line 1024, in _handle_dbapi_exception
    exc_info
  File "/Users/zorba/anaconda2/lib/python2.7/site-packages/sqlalchemy/util/compat.py", line 196, in raise_from_cause
    reraise(type(exception), exception, tb=exc_tb)
  File "/Users/zorba/anaconda2/lib/python2.7/site-packages/sqlalchemy/engine/base.py", line 867, in _execute_context
    context)
  File "/Users/zorba/anaconda2/lib/python2.7/site-packages/sqlalchemy/engine/default.py", line 324, in do_execute
    cursor.execute(statement, parameters)
OperationalError: (OperationalError) no such table: swaps u'SELECT count(*) AS count_1 \nFROM (SELECT swaps.uniqueid AS swaps_uniqueid, swaps.assignmentid AS swaps_assignmentid, swaps.workerid AS swaps_workerid, swaps.hitid AS swaps_hitid, swaps.ipaddress AS swaps_ipaddress, swaps.browser AS swaps_browser, swaps.platform AS swaps_platform, swaps.language AS swaps_language, swaps.cond AS swaps_cond, swaps.counterbalance AS swaps_counterbalance, swaps.codeversion AS swaps_codeversion, swaps.beginhit AS swaps_beginhit, swaps.beginexp AS swaps_beginexp, swaps.endhit AS swaps_endhit, swaps.bonus AS swaps_bonus, swaps.status AS swaps_status, swaps.datastring AS swaps_datastring \nFROM swaps \nWHERE swaps.assignmentid != ? AND swaps.workerid = ?) AS anon_1' (u'debugVULX35', u'debugD86PNU')
2016-11-30 12:30:28,673 Exception on /exp [GET]
Traceback (most recent call last):
  File "/Users/zorba/anaconda2/lib/python2.7/site-packages/flask/app.py", line 1817, in wsgi_app
    response = self.full_dispatch_request()
  File "/Users/zorba/anaconda2/lib/python2.7/site-packages/flask/app.py", line 1477, in full_dispatch_request
    rv = self.handle_user_exception(e)
  File "/Users/zorba/anaconda2/lib/python2.7/site-packages/flask/app.py", line 1381, in handle_user_exception
    reraise(exc_type, exc_value, tb)
  File "/Users/zorba/anaconda2/lib/python2.7/site-packages/flask/app.py", line 1475, in full_dispatch_request
    rv = self.dispatch_request()
  File "/Users/zorba/anaconda2/lib/python2.7/site-packages/flask/app.py", line 1461, in dispatch_request
    return self.view_functions[rule.endpoint](**req.view_args)
  File "/Users/zorba/anaconda2/lib/python2.7/site-packages/psiturk/user_utils.py", line 20, in new_func
    resp = make_response(func(*args, **kwargs))
  File "/Users/zorba/anaconda2/lib/python2.7/site-packages/psiturk/experiment.py", line 365, in start_exp
    filter(Participant.workerid == worker_id).\
  File "/Users/zorba/anaconda2/lib/python2.7/site-packages/sqlalchemy/orm/query.py", line 2241, in all
    return list(self)
  File "/Users/zorba/anaconda2/lib/python2.7/site-packages/sqlalchemy/orm/query.py", line 2353, in __iter__
    return self._execute_and_instances(context)
  File "/Users/zorba/anaconda2/lib/python2.7/site-packages/sqlalchemy/orm/query.py", line 2368, in _execute_and_instances
    result = conn.execute(querycontext.statement, self._params)
  File "/Users/zorba/anaconda2/lib/python2.7/site-packages/sqlalchemy/engine/base.py", line 662, in execute
    params)
  File "/Users/zorba/anaconda2/lib/python2.7/site-packages/sqlalchemy/engine/base.py", line 761, in _execute_clauseelement
    compiled_sql, distilled_params
  File "/Users/zorba/anaconda2/lib/python2.7/site-packages/sqlalchemy/engine/base.py", line 874, in _execute_context
    context)
  File "/Users/zorba/anaconda2/lib/python2.7/site-packages/sqlalchemy/engine/base.py", line 1024, in _handle_dbapi_exception
    exc_info
  File "/Users/zorba/anaconda2/lib/python2.7/site-packages/sqlalchemy/util/compat.py", line 196, in raise_from_cause
    reraise(type(exception), exception, tb=exc_tb)
  File "/Users/zorba/anaconda2/lib/python2.7/site-packages/sqlalchemy/engine/base.py", line 867, in _execute_context
    context)
  File "/Users/zorba/anaconda2/lib/python2.7/site-packages/sqlalchemy/engine/default.py", line 324, in do_execute
    cursor.execute(statement, parameters)
OperationalError: (OperationalError) no such table: swaps u'SELECT swaps.uniqueid AS swaps_uniqueid, swaps.assignmentid AS swaps_assignmentid, swaps.workerid AS swaps_workerid, swaps.hitid AS swaps_hitid, swaps.ipaddress AS swaps_ipaddress, swaps.browser AS swaps_browser, swaps.platform AS swaps_platform, swaps.language AS swaps_language, swaps.cond AS swaps_cond, swaps.counterbalance AS swaps_counterbalance, swaps.codeversion AS swaps_codeversion, swaps.beginhit AS swaps_beginhit, swaps.beginexp AS swaps_beginexp, swaps.endhit AS swaps_endhit, swaps.bonus AS swaps_bonus, swaps.status AS swaps_status, swaps.datastring AS swaps_datastring \nFROM swaps \nWHERE swaps.workerid = ?' (u'debugOE5FSD',)
[2016-11-30 13:02:12 -0500] [28780] [CRITICAL] WORKER TIMEOUT (pid:28784)
[2016-11-30 13:02:12 -0500] [28780] [CRITICAL] WORKER TIMEOUT (pid:28785)
[2016-11-30 13:02:12 -0500] [28780] [CRITICAL] WORKER TIMEOUT (pid:28786)
[2016-11-30 13:02:12 -0500] [28780] [CRITICAL] WORKER TIMEOUT (pid:28787)
[2016-11-30 13:02:12 -0500] [28780] [CRITICAL] WORKER TIMEOUT (pid:28788)
[2016-11-30 13:02:12 -0500] [28780] [CRITICAL] WORKER TIMEOUT (pid:28789)
[2016-11-30 13:02:12 -0500] [28780] [CRITICAL] WORKER TIMEOUT (pid:28790)
[2016-11-30 13:02:12 -0500] [28780] [CRITICAL] WORKER TIMEOUT (pid:28791)
[2016-11-30 13:02:12 -0500] [28780] [CRITICAL] WORKER TIMEOUT (pid:28792)
[2016-11-30 13:02:22 -0500] [28891] [ERROR] Exception in worker process
Traceback (most recent call last):
  File "/Users/zorba/anaconda2/lib/python2.7/site-packages/gunicorn/arbiter.py", line 557, in spawn_worker
    worker.init_process()
  File "/Users/zorba/anaconda2/lib/python2.7/site-packages/gunicorn/workers/base.py", line 126, in init_process
    self.load_wsgi()
  File "/Users/zorba/anaconda2/lib/python2.7/site-packages/gunicorn/workers/base.py", line 136, in load_wsgi
    self.wsgi = self.app.wsgi()
  File "/Users/zorba/anaconda2/lib/python2.7/site-packages/gunicorn/app/base.py", line 67, in wsgi
    self.callable = self.load()
  File "/Users/zorba/anaconda2/lib/python2.7/site-packages/psiturk/experiment_server.py", line 47, in load
    return util.import_app("psiturk.experiment:app")
  File "/Users/zorba/anaconda2/lib/python2.7/site-packages/gunicorn/util.py", line 357, in import_app
    __import__(module)
  File "/Users/zorba/anaconda2/lib/python2.7/site-packages/psiturk/experiment.py", line 72, in <module>
    from custom import custom_code
  File "/Users/zorba/Dropbox/Neuro/psiturk/Swaps-no-fix/custom.py", line 29, in <module>
    all_trials = load(f)
  File "/Users/zorba/anaconda2/lib/python2.7/pickle.py", line 1384, in load
    return Unpickler(file).load()
  File "/Users/zorba/anaconda2/lib/python2.7/pickle.py", line 864, in load
    dispatch[key](self)
  File "/Users/zorba/anaconda2/lib/python2.7/pickle.py", line 886, in load_eof
    raise EOFError
EOFError
[2016-11-30 13:02:22 -0500] [28892] [ERROR] Exception in worker process
Traceback (most recent call last):
  File "/Users/zorba/anaconda2/lib/python2.7/site-packages/gunicorn/arbiter.py", line 557, in spawn_worker
    worker.init_process()
  File "/Users/zorba/anaconda2/lib/python2.7/site-packages/gunicorn/workers/base.py", line 126, in init_process
    self.load_wsgi()
  File "/Users/zorba/anaconda2/lib/python2.7/site-packages/gunicorn/workers/base.py", line 136, in load_wsgi
    self.wsgi = self.app.wsgi()
  File "/Users/zorba/anaconda2/lib/python2.7/site-packages/gunicorn/app/base.py", line 67, in wsgi
    self.callable = self.load()
  File "/Users/zorba/anaconda2/lib/python2.7/site-packages/psiturk/experiment_server.py", line 47, in load
    return util.import_app("psiturk.experiment:app")
  File "/Users/zorba/anaconda2/lib/python2.7/site-packages/gunicorn/util.py", line 357, in import_app
    __import__(module)
  File "/Users/zorba/anaconda2/lib/python2.7/site-packages/psiturk/experiment.py", line 72, in <module>
    from custom import custom_code
  File "/Users/zorba/Dropbox/Neuro/psiturk/Swaps-no-fix/custom.py", line 29, in <module>
    all_trials = load(f)
  File "/Users/zorba/anaconda2/lib/python2.7/pickle.py", line 1384, in load
    return Unpickler(file).load()
  File "/Users/zorba/anaconda2/lib/python2.7/pickle.py", line 864, in load
    dispatch[key](self)
  File "/Users/zorba/anaconda2/lib/python2.7/pickle.py", line 886, in load_eof
    raise EOFError
EOFError
[2016-11-30 13:02:23 -0500] [28895] [ERROR] Exception in worker process
Traceback (most recent call last):
  File "/Users/zorba/anaconda2/lib/python2.7/site-packages/gunicorn/arbiter.py", line 557, in spawn_worker
    worker.init_process()
  File "/Users/zorba/anaconda2/lib/python2.7/site-packages/gunicorn/workers/base.py", line 126, in init_process
    self.load_wsgi()
  File "/Users/zorba/anaconda2/lib/python2.7/site-packages/gunicorn/workers/base.py", line 136, in load_wsgi
    self.wsgi = self.app.wsgi()
  File "/Users/zorba/anaconda2/lib/python2.7/site-packages/gunicorn/app/base.py", line 67, in wsgi
    self.callable = self.load()
  File "/Users/zorba/anaconda2/lib/python2.7/site-packages/psiturk/experiment_server.py", line 47, in load
    return util.import_app("psiturk.experiment:app")
  File "/Users/zorba/anaconda2/lib/python2.7/site-packages/gunicorn/util.py", line 357, in import_app
    __import__(module)
  File "/Users/zorba/anaconda2/lib/python2.7/site-packages/psiturk/experiment.py", line 72, in <module>
    from custom import custom_code
  File "/Users/zorba/Dropbox/Neuro/psiturk/Swaps-no-fix/custom.py", line 29, in <module>
    all_trials = load(f)
  File "/Users/zorba/anaconda2/lib/python2.7/pickle.py", line 1384, in load
    return Unpickler(file).load()
  File "/Users/zorba/anaconda2/lib/python2.7/pickle.py", line 864, in load
    dispatch[key](self)
  File "/Users/zorba/anaconda2/lib/python2.7/pickle.py", line 886, in load_eof
    raise EOFError
EOFError
[2016-11-30 13:02:23 -0500] [28893] [ERROR] Exception in worker process
Traceback (most recent call last):
  File "/Users/zorba/anaconda2/lib/python2.7/site-packages/gunicorn/arbiter.py", line 557, in spawn_worker
    worker.init_process()
  File "/Users/zorba/anaconda2/lib/python2.7/site-packages/gunicorn/workers/base.py", line 126, in init_process
    self.load_wsgi()
  File "/Users/zorba/anaconda2/lib/python2.7/site-packages/gunicorn/workers/base.py", line 136, in load_wsgi
    self.wsgi = self.app.wsgi()
  File "/Users/zorba/anaconda2/lib/python2.7/site-packages/gunicorn/app/base.py", line 67, in wsgi
    self.callable = self.load()
  File "/Users/zorba/anaconda2/lib/python2.7/site-packages/psiturk/experiment_server.py", line 47, in load
    return util.import_app("psiturk.experiment:app")
  File "/Users/zorba/anaconda2/lib/python2.7/site-packages/gunicorn/util.py", line 357, in import_app
    __import__(module)
  File "/Users/zorba/anaconda2/lib/python2.7/site-packages/psiturk/experiment.py", line 72, in <module>
    from custom import custom_code
  File "/Users/zorba/Dropbox/Neuro/psiturk/Swaps-no-fix/custom.py", line 29, in <module>
    all_trials = load(f)
  File "/Users/zorba/anaconda2/lib/python2.7/pickle.py", line 1384, in load
    return Unpickler(file).load()
  File "/Users/zorba/anaconda2/lib/python2.7/pickle.py", line 864, in load
    dispatch[key](self)
  File "/Users/zorba/anaconda2/lib/python2.7/pickle.py", line 886, in load_eof
    raise EOFError
EOFError
[2016-11-30 13:02:23 -0500] [28897] [ERROR] Exception in worker process
Traceback (most recent call last):
  File "/Users/zorba/anaconda2/lib/python2.7/site-packages/gunicorn/arbiter.py", line 557, in spawn_worker
    worker.init_process()
  File "/Users/zorba/anaconda2/lib/python2.7/site-packages/gunicorn/workers/base.py", line 126, in init_process
    self.load_wsgi()
  File "/Users/zorba/anaconda2/lib/python2.7/site-packages/gunicorn/workers/base.py", line 136, in load_wsgi
    self.wsgi = self.app.wsgi()
  File "/Users/zorba/anaconda2/lib/python2.7/site-packages/gunicorn/app/base.py", line 67, in wsgi
    self.callable = self.load()
  File "/Users/zorba/anaconda2/lib/python2.7/site-packages/psiturk/experiment_server.py", line 47, in load
    return util.import_app("psiturk.experiment:app")
  File "/Users/zorba/anaconda2/lib/python2.7/site-packages/gunicorn/util.py", line 357, in import_app
    __import__(module)
  File "/Users/zorba/anaconda2/lib/python2.7/site-packages/psiturk/experiment.py", line 72, in <module>
    from custom import custom_code
  File "/Users/zorba/Dropbox/Neuro/psiturk/Swaps-no-fix/custom.py", line 29, in <module>
    all_trials = load(f)
  File "/Users/zorba/anaconda2/lib/python2.7/pickle.py", line 1384, in load
    return Unpickler(file).load()
  File "/Users/zorba/anaconda2/lib/python2.7/pickle.py", line 864, in load
    dispatch[key](self)
  File "/Users/zorba/anaconda2/lib/python2.7/pickle.py", line 886, in load_eof
    raise EOFError
EOFError
[2016-11-30 13:02:23 -0500] [28898] [ERROR] Exception in worker process
Traceback (most recent call last):
  File "/Users/zorba/anaconda2/lib/python2.7/site-packages/gunicorn/arbiter.py", line 557, in spawn_worker
    worker.init_process()
  File "/Users/zorba/anaconda2/lib/python2.7/site-packages/gunicorn/workers/base.py", line 126, in init_process
    self.load_wsgi()
  File "/Users/zorba/anaconda2/lib/python2.7/site-packages/gunicorn/workers/base.py", line 136, in load_wsgi
    self.wsgi = self.app.wsgi()
  File "/Users/zorba/anaconda2/lib/python2.7/site-packages/gunicorn/app/base.py", line 67, in wsgi
    self.callable = self.load()
  File "/Users/zorba/anaconda2/lib/python2.7/site-packages/psiturk/experiment_server.py", line 47, in load
    return util.import_app("psiturk.experiment:app")
  File "/Users/zorba/anaconda2/lib/python2.7/site-packages/gunicorn/util.py", line 357, in import_app
    __import__(module)
  File "/Users/zorba/anaconda2/lib/python2.7/site-packages/psiturk/experiment.py", line 72, in <module>
    from custom import custom_code
  File "/Users/zorba/Dropbox/Neuro/psiturk/Swaps-no-fix/custom.py", line 29, in <module>
    all_trials = load(f)
  File "/Users/zorba/anaconda2/lib/python2.7/pickle.py", line 1384, in load
    return Unpickler(file).load()
  File "/Users/zorba/anaconda2/lib/python2.7/pickle.py", line 864, in load
    dispatch[key](self)
  File "/Users/zorba/anaconda2/lib/python2.7/pickle.py", line 886, in load_eof
    raise EOFError
EOFError
[2016-11-30 13:02:23 -0500] [28896] [ERROR] Exception in worker process
Traceback (most recent call last):
  File "/Users/zorba/anaconda2/lib/python2.7/site-packages/gunicorn/arbiter.py", line 557, in spawn_worker
    worker.init_process()
  File "/Users/zorba/anaconda2/lib/python2.7/site-packages/gunicorn/workers/base.py", line 126, in init_process
    self.load_wsgi()
  File "/Users/zorba/anaconda2/lib/python2.7/site-packages/gunicorn/workers/base.py", line 136, in load_wsgi
    self.wsgi = self.app.wsgi()
  File "/Users/zorba/anaconda2/lib/python2.7/site-packages/gunicorn/app/base.py", line 67, in wsgi
    self.callable = self.load()
  File "/Users/zorba/anaconda2/lib/python2.7/site-packages/psiturk/experiment_server.py", line 47, in load
    return util.import_app("psiturk.experiment:app")
  File "/Users/zorba/anaconda2/lib/python2.7/site-packages/gunicorn/util.py", line 357, in import_app
    __import__(module)
  File "/Users/zorba/anaconda2/lib/python2.7/site-packages/psiturk/experiment.py", line 72, in <module>
    from custom import custom_code
  File "/Users/zorba/Dropbox/Neuro/psiturk/Swaps-no-fix/custom.py", line 29, in <module>
    all_trials = load(f)
  File "/Users/zorba/anaconda2/lib/python2.7/pickle.py", line 1384, in load
    return Unpickler(file).load()
  File "/Users/zorba/anaconda2/lib/python2.7/pickle.py", line 864, in load
    dispatch[key](self)
  File "/Users/zorba/anaconda2/lib/python2.7/pickle.py", line 886, in load_eof
    raise EOFError
EOFError
[2016-11-30 13:02:23 -0500] [28894] [ERROR] Exception in worker process
Traceback (most recent call last):
  File "/Users/zorba/anaconda2/lib/python2.7/site-packages/gunicorn/arbiter.py", line 557, in spawn_worker
    worker.init_process()
  File "/Users/zorba/anaconda2/lib/python2.7/site-packages/gunicorn/workers/base.py", line 126, in init_process
    self.load_wsgi()
  File "/Users/zorba/anaconda2/lib/python2.7/site-packages/gunicorn/workers/base.py", line 136, in load_wsgi
    self.wsgi = self.app.wsgi()
  File "/Users/zorba/anaconda2/lib/python2.7/site-packages/gunicorn/app/base.py", line 67, in wsgi
    self.callable = self.load()
  File "/Users/zorba/anaconda2/lib/python2.7/site-packages/psiturk/experiment_server.py", line 47, in load
    return util.import_app("psiturk.experiment:app")
  File "/Users/zorba/anaconda2/lib/python2.7/site-packages/gunicorn/util.py", line 357, in import_app
    __import__(module)
  File "/Users/zorba/anaconda2/lib/python2.7/site-packages/psiturk/experiment.py", line 72, in <module>
    from custom import custom_code
  File "/Users/zorba/Dropbox/Neuro/psiturk/Swaps-no-fix/custom.py", line 29, in <module>
    all_trials = load(f)
  File "/Users/zorba/anaconda2/lib/python2.7/pickle.py", line 1384, in load
    return Unpickler(file).load()
  File "/Users/zorba/anaconda2/lib/python2.7/pickle.py", line 864, in load
    dispatch[key](self)
  File "/Users/zorba/anaconda2/lib/python2.7/pickle.py", line 886, in load_eof
    raise EOFError
EOFError
[2016-11-30 13:02:23 -0500] [28899] [ERROR] Exception in worker process
Traceback (most recent call last):
  File "/Users/zorba/anaconda2/lib/python2.7/site-packages/gunicorn/arbiter.py", line 557, in spawn_worker
    worker.init_process()
  File "/Users/zorba/anaconda2/lib/python2.7/site-packages/gunicorn/workers/base.py", line 126, in init_process
    self.load_wsgi()
  File "/Users/zorba/anaconda2/lib/python2.7/site-packages/gunicorn/workers/base.py", line 136, in load_wsgi
    self.wsgi = self.app.wsgi()
  File "/Users/zorba/anaconda2/lib/python2.7/site-packages/gunicorn/app/base.py", line 67, in wsgi
    self.callable = self.load()
  File "/Users/zorba/anaconda2/lib/python2.7/site-packages/psiturk/experiment_server.py", line 47, in load
    return util.import_app("psiturk.experiment:app")
  File "/Users/zorba/anaconda2/lib/python2.7/site-packages/gunicorn/util.py", line 357, in import_app
    __import__(module)
  File "/Users/zorba/anaconda2/lib/python2.7/site-packages/psiturk/experiment.py", line 72, in <module>
    from custom import custom_code
  File "/Users/zorba/Dropbox/Neuro/psiturk/Swaps-no-fix/custom.py", line 29, in <module>
    all_trials = load(f)
  File "/Users/zorba/anaconda2/lib/python2.7/pickle.py", line 1384, in load
    return Unpickler(file).load()
  File "/Users/zorba/anaconda2/lib/python2.7/pickle.py", line 864, in load
    dispatch[key](self)
  File "/Users/zorba/anaconda2/lib/python2.7/pickle.py", line 886, in load_eof
    raise EOFError
EOFError
2016-11-30 14:21:37,610 Exception on /ad [GET]
Traceback (most recent call last):
  File "/Users/zorba/anaconda2/lib/python2.7/site-packages/flask/app.py", line 1817, in wsgi_app
    response = self.full_dispatch_request()
  File "/Users/zorba/anaconda2/lib/python2.7/site-packages/flask/app.py", line 1477, in full_dispatch_request
    rv = self.handle_user_exception(e)
  File "/Users/zorba/anaconda2/lib/python2.7/site-packages/flask/app.py", line 1381, in handle_user_exception
    reraise(exc_type, exc_value, tb)
  File "/Users/zorba/anaconda2/lib/python2.7/site-packages/flask/app.py", line 1475, in full_dispatch_request
    rv = self.dispatch_request()
  File "/Users/zorba/anaconda2/lib/python2.7/site-packages/flask/app.py", line 1461, in dispatch_request
    return self.view_functions[rule.endpoint](**req.view_args)
  File "/Users/zorba/anaconda2/lib/python2.7/site-packages/psiturk/user_utils.py", line 20, in new_func
    resp = make_response(func(*args, **kwargs))
  File "/Users/zorba/anaconda2/lib/python2.7/site-packages/psiturk/experiment.py", line 249, in advertisement
    filter(Participant.workerid == worker_id).\
  File "/Users/zorba/anaconda2/lib/python2.7/site-packages/sqlalchemy/orm/query.py", line 2535, in count
    return self.from_self(col).scalar()
  File "/Users/zorba/anaconda2/lib/python2.7/site-packages/sqlalchemy/orm/query.py", line 2341, in scalar
    ret = self.one()
  File "/Users/zorba/anaconda2/lib/python2.7/site-packages/sqlalchemy/orm/query.py", line 2310, in one
    ret = list(self)
  File "/Users/zorba/anaconda2/lib/python2.7/site-packages/sqlalchemy/orm/query.py", line 2353, in __iter__
    return self._execute_and_instances(context)
  File "/Users/zorba/anaconda2/lib/python2.7/site-packages/sqlalchemy/orm/query.py", line 2368, in _execute_and_instances
    result = conn.execute(querycontext.statement, self._params)
  File "/Users/zorba/anaconda2/lib/python2.7/site-packages/sqlalchemy/engine/base.py", line 662, in execute
    params)
  File "/Users/zorba/anaconda2/lib/python2.7/site-packages/sqlalchemy/engine/base.py", line 761, in _execute_clauseelement
    compiled_sql, distilled_params
  File "/Users/zorba/anaconda2/lib/python2.7/site-packages/sqlalchemy/engine/base.py", line 874, in _execute_context
    context)
  File "/Users/zorba/anaconda2/lib/python2.7/site-packages/sqlalchemy/engine/base.py", line 1024, in _handle_dbapi_exception
    exc_info
  File "/Users/zorba/anaconda2/lib/python2.7/site-packages/sqlalchemy/util/compat.py", line 196, in raise_from_cause
    reraise(type(exception), exception, tb=exc_tb)
  File "/Users/zorba/anaconda2/lib/python2.7/site-packages/sqlalchemy/engine/base.py", line 867, in _execute_context
    context)
  File "/Users/zorba/anaconda2/lib/python2.7/site-packages/sqlalchemy/engine/default.py", line 324, in do_execute
    cursor.execute(statement, parameters)
OperationalError: (OperationalError) no such table: swaps u'SELECT count(*) AS count_1 \nFROM (SELECT swaps.uniqueid AS swaps_uniqueid, swaps.assignmentid AS swaps_assignmentid, swaps.workerid AS swaps_workerid, swaps.hitid AS swaps_hitid, swaps.ipaddress AS swaps_ipaddress, swaps.browser AS swaps_browser, swaps.platform AS swaps_platform, swaps.language AS swaps_language, swaps.cond AS swaps_cond, swaps.counterbalance AS swaps_counterbalance, swaps.codeversion AS swaps_codeversion, swaps.beginhit AS swaps_beginhit, swaps.beginexp AS swaps_beginexp, swaps.endhit AS swaps_endhit, swaps.bonus AS swaps_bonus, swaps.status AS swaps_status, swaps.datastring AS swaps_datastring \nFROM swaps \nWHERE swaps.assignmentid != ? AND swaps.workerid = ?) AS anon_1' (u'debugEV0GE3', u'debug01PGO4')
[2016-11-30 15:03:42 -0500] [29263] [CRITICAL] WORKER TIMEOUT (pid:29267)
[2016-11-30 15:03:42 -0500] [29263] [CRITICAL] WORKER TIMEOUT (pid:29268)
[2016-11-30 15:03:42 -0500] [29263] [CRITICAL] WORKER TIMEOUT (pid:29269)
[2016-11-30 15:03:42 -0500] [29263] [CRITICAL] WORKER TIMEOUT (pid:29270)
[2016-11-30 15:03:42 -0500] [29263] [CRITICAL] WORKER TIMEOUT (pid:29271)
[2016-11-30 15:03:42 -0500] [29263] [CRITICAL] WORKER TIMEOUT (pid:29272)
[2016-11-30 15:03:42 -0500] [29263] [CRITICAL] WORKER TIMEOUT (pid:29273)
[2016-11-30 15:03:42 -0500] [29263] [CRITICAL] WORKER TIMEOUT (pid:29274)
[2016-11-30 15:03:42 -0500] [29263] [CRITICAL] WORKER TIMEOUT (pid:29275)
[2016-11-30 15:36:59 -0500] [29263] [CRITICAL] WORKER TIMEOUT (pid:29462)
[2016-11-30 15:36:59 -0500] [29263] [CRITICAL] WORKER TIMEOUT (pid:29460)
[2016-11-30 15:36:59 -0500] [29263] [CRITICAL] WORKER TIMEOUT (pid:29463)
[2016-11-30 15:36:59 -0500] [29263] [CRITICAL] WORKER TIMEOUT (pid:29464)
[2016-11-30 15:36:59 -0500] [29263] [CRITICAL] WORKER TIMEOUT (pid:29465)
[2016-11-30 15:36:59 -0500] [29263] [CRITICAL] WORKER TIMEOUT (pid:29466)
[2016-11-30 15:36:59 -0500] [29263] [CRITICAL] WORKER TIMEOUT (pid:29467)
[2016-11-30 15:36:59 -0500] [29263] [CRITICAL] WORKER TIMEOUT (pid:29468)
[2016-11-30 15:36:59 -0500] [29263] [CRITICAL] WORKER TIMEOUT (pid:29461)
2016-11-30 16:02:24,034 Exception on /get_stims [GET]
Traceback (most recent call last):
  File "/Users/zorba/anaconda2/lib/python2.7/site-packages/flask/app.py", line 1817, in wsgi_app
    response = self.full_dispatch_request()
  File "/Users/zorba/anaconda2/lib/python2.7/site-packages/flask/app.py", line 1477, in full_dispatch_request
    rv = self.handle_user_exception(e)
  File "/Users/zorba/anaconda2/lib/python2.7/site-packages/flask/app.py", line 1381, in handle_user_exception
    reraise(exc_type, exc_value, tb)
  File "/Users/zorba/anaconda2/lib/python2.7/site-packages/flask/app.py", line 1475, in full_dispatch_request
    rv = self.dispatch_request()
  File "/Users/zorba/anaconda2/lib/python2.7/site-packages/flask/app.py", line 1461, in dispatch_request
    return self.view_functions[rule.endpoint](**req.view_args)
  File "/Users/zorba/Dropbox/Neuro/psiturk/Swaps-no-fix/custom.py", line 128, in get_stims
    params["stims"]  = map(int,params["stims"].split(","))
ValueError: invalid literal for int() with base 10: ''
2016-11-30 16:02:26,673 Exception on /get_stims [GET]
Traceback (most recent call last):
  File "/Users/zorba/anaconda2/lib/python2.7/site-packages/flask/app.py", line 1817, in wsgi_app
    response = self.full_dispatch_request()
  File "/Users/zorba/anaconda2/lib/python2.7/site-packages/flask/app.py", line 1477, in full_dispatch_request
    rv = self.handle_user_exception(e)
  File "/Users/zorba/anaconda2/lib/python2.7/site-packages/flask/app.py", line 1381, in handle_user_exception
    reraise(exc_type, exc_value, tb)
  File "/Users/zorba/anaconda2/lib/python2.7/site-packages/flask/app.py", line 1475, in full_dispatch_request
    rv = self.dispatch_request()
  File "/Users/zorba/anaconda2/lib/python2.7/site-packages/flask/app.py", line 1461, in dispatch_request
    return self.view_functions[rule.endpoint](**req.view_args)
  File "/Users/zorba/Dropbox/Neuro/psiturk/Swaps-no-fix/custom.py", line 128, in get_stims
    params["stims"]  = map(int,params["stims"].split(","))
ValueError: invalid literal for int() with base 10: ''
2016-11-30 16:02:33,642 Exception on /get_stims [GET]
Traceback (most recent call last):
  File "/Users/zorba/anaconda2/lib/python2.7/site-packages/flask/app.py", line 1817, in wsgi_app
    response = self.full_dispatch_request()
  File "/Users/zorba/anaconda2/lib/python2.7/site-packages/flask/app.py", line 1477, in full_dispatch_request
    rv = self.handle_user_exception(e)
  File "/Users/zorba/anaconda2/lib/python2.7/site-packages/flask/app.py", line 1381, in handle_user_exception
    reraise(exc_type, exc_value, tb)
  File "/Users/zorba/anaconda2/lib/python2.7/site-packages/flask/app.py", line 1475, in full_dispatch_request
    rv = self.dispatch_request()
  File "/Users/zorba/anaconda2/lib/python2.7/site-packages/flask/app.py", line 1461, in dispatch_request
    return self.view_functions[rule.endpoint](**req.view_args)
  File "/Users/zorba/Dropbox/Neuro/psiturk/Swaps-no-fix/custom.py", line 128, in get_stims
    params["stims"]  = map(int,params["stims"].split(","))
ValueError: invalid literal for int() with base 10: ''
[2016-11-30 17:34:02 -0500] [29263] [CRITICAL] WORKER TIMEOUT (pid:29527)
[2016-11-30 17:34:02 -0500] [29263] [CRITICAL] WORKER TIMEOUT (pid:29528)
[2016-11-30 17:34:02 -0500] [29263] [CRITICAL] WORKER TIMEOUT (pid:29525)
[2016-11-30 17:34:02 -0500] [29263] [CRITICAL] WORKER TIMEOUT (pid:29526)
[2016-11-30 17:34:02 -0500] [29263] [CRITICAL] WORKER TIMEOUT (pid:29529)
[2016-11-30 17:34:02 -0500] [29263] [CRITICAL] WORKER TIMEOUT (pid:29530)
[2016-11-30 17:34:02 -0500] [29263] [CRITICAL] WORKER TIMEOUT (pid:29531)
[2016-11-30 17:34:02 -0500] [29263] [CRITICAL] WORKER TIMEOUT (pid:29532)
[2016-11-30 17:34:02 -0500] [29263] [CRITICAL] WORKER TIMEOUT (pid:29533)
[2016-11-30 20:50:38 -0500] [29980] [CRITICAL] WORKER TIMEOUT (pid:29984)
[2016-11-30 20:50:38 -0500] [29980] [CRITICAL] WORKER TIMEOUT (pid:29985)
[2016-11-30 20:50:38 -0500] [29980] [CRITICAL] WORKER TIMEOUT (pid:29986)
[2016-11-30 20:50:38 -0500] [29980] [CRITICAL] WORKER TIMEOUT (pid:29987)
[2016-11-30 20:50:38 -0500] [29980] [CRITICAL] WORKER TIMEOUT (pid:29988)
[2016-11-30 20:50:38 -0500] [29980] [CRITICAL] WORKER TIMEOUT (pid:29989)
[2016-11-30 20:50:38 -0500] [29980] [CRITICAL] WORKER TIMEOUT (pid:29990)
[2016-11-30 20:50:38 -0500] [29980] [CRITICAL] WORKER TIMEOUT (pid:29991)
[2016-11-30 20:50:38 -0500] [29980] [CRITICAL] WORKER TIMEOUT (pid:29992)
[2016-11-30 22:22:29 -0500] [29980] [CRITICAL] WORKER TIMEOUT (pid:30092)
[2016-11-30 22:22:29 -0500] [29980] [CRITICAL] WORKER TIMEOUT (pid:30093)
[2016-11-30 22:22:29 -0500] [29980] [CRITICAL] WORKER TIMEOUT (pid:30094)
[2016-11-30 22:22:29 -0500] [29980] [CRITICAL] WORKER TIMEOUT (pid:30095)
[2016-11-30 22:22:29 -0500] [29980] [CRITICAL] WORKER TIMEOUT (pid:30096)
[2016-11-30 22:22:29 -0500] [29980] [CRITICAL] WORKER TIMEOUT (pid:30097)
[2016-11-30 22:22:29 -0500] [29980] [CRITICAL] WORKER TIMEOUT (pid:30098)
[2016-11-30 22:22:29 -0500] [29980] [CRITICAL] WORKER TIMEOUT (pid:30099)
[2016-11-30 22:22:29 -0500] [29980] [CRITICAL] WORKER TIMEOUT (pid:30100)
[2016-12-01 08:52:24 -0500] [29980] [CRITICAL] WORKER TIMEOUT (pid:30112)
[2016-12-01 08:52:24 -0500] [29980] [CRITICAL] WORKER TIMEOUT (pid:30113)
[2016-12-01 08:52:24 -0500] [29980] [CRITICAL] WORKER TIMEOUT (pid:30114)
[2016-12-01 08:52:24 -0500] [29980] [CRITICAL] WORKER TIMEOUT (pid:30115)
[2016-12-01 08:52:24 -0500] [29980] [CRITICAL] WORKER TIMEOUT (pid:30116)
[2016-12-01 08:52:24 -0500] [29980] [CRITICAL] WORKER TIMEOUT (pid:30108)
[2016-12-01 08:52:24 -0500] [29980] [CRITICAL] WORKER TIMEOUT (pid:30109)
[2016-12-01 08:52:24 -0500] [29980] [CRITICAL] WORKER TIMEOUT (pid:30110)
[2016-12-01 08:52:24 -0500] [29980] [CRITICAL] WORKER TIMEOUT (pid:30111)
[2016-12-01 09:55:42 -0500] [29980] [CRITICAL] WORKER TIMEOUT (pid:31943)
[2016-12-01 09:55:42 -0500] [29980] [CRITICAL] WORKER TIMEOUT (pid:31944)
[2016-12-01 09:55:42 -0500] [29980] [CRITICAL] WORKER TIMEOUT (pid:31945)
[2016-12-01 09:55:42 -0500] [29980] [CRITICAL] WORKER TIMEOUT (pid:31946)
[2016-12-01 09:55:42 -0500] [29980] [CRITICAL] WORKER TIMEOUT (pid:31947)
[2016-12-01 09:55:42 -0500] [29980] [CRITICAL] WORKER TIMEOUT (pid:31948)
[2016-12-01 09:55:42 -0500] [29980] [CRITICAL] WORKER TIMEOUT (pid:31949)
[2016-12-01 09:55:42 -0500] [29980] [CRITICAL] WORKER TIMEOUT (pid:31950)
[2016-12-01 09:55:42 -0500] [29980] [CRITICAL] WORKER TIMEOUT (pid:31951)
[2016-12-01 12:09:05 -0500] [32655] [CRITICAL] WORKER TIMEOUT (pid:32659)
[2016-12-01 12:09:05 -0500] [32655] [CRITICAL] WORKER TIMEOUT (pid:32660)
[2016-12-01 12:09:05 -0500] [32655] [CRITICAL] WORKER TIMEOUT (pid:32661)
[2016-12-01 12:09:05 -0500] [32655] [CRITICAL] WORKER TIMEOUT (pid:32662)
[2016-12-01 12:09:05 -0500] [32655] [CRITICAL] WORKER TIMEOUT (pid:32663)
[2016-12-01 12:09:05 -0500] [32655] [CRITICAL] WORKER TIMEOUT (pid:32664)
[2016-12-01 12:09:05 -0500] [32655] [CRITICAL] WORKER TIMEOUT (pid:32665)
[2016-12-01 12:09:05 -0500] [32655] [CRITICAL] WORKER TIMEOUT (pid:32666)
[2016-12-01 12:09:05 -0500] [32655] [CRITICAL] WORKER TIMEOUT (pid:32667)
[2016-12-02 18:44:31 -0500] [37413] [CRITICAL] WORKER TIMEOUT (pid:37417)
[2016-12-02 18:44:31 -0500] [37413] [CRITICAL] WORKER TIMEOUT (pid:37418)
[2016-12-02 18:44:31 -0500] [37413] [CRITICAL] WORKER TIMEOUT (pid:37419)
[2016-12-02 18:44:31 -0500] [37413] [CRITICAL] WORKER TIMEOUT (pid:37420)
[2016-12-02 18:44:31 -0500] [37413] [CRITICAL] WORKER TIMEOUT (pid:37421)
[2016-12-02 18:44:31 -0500] [37413] [CRITICAL] WORKER TIMEOUT (pid:37422)
[2016-12-02 18:44:31 -0500] [37413] [CRITICAL] WORKER TIMEOUT (pid:37423)
[2016-12-02 18:44:31 -0500] [37413] [CRITICAL] WORKER TIMEOUT (pid:37424)
[2016-12-02 18:44:31 -0500] [37413] [CRITICAL] WORKER TIMEOUT (pid:37425)
2016-12-02 21:59:53,183 Exception on /d [GET]
Traceback (most recent call last):
  File "/Users/zorba/anaconda2/lib/python2.7/site-packages/flask/app.py", line 1817, in wsgi_app
    response = self.full_dispatch_request()
  File "/Users/zorba/anaconda2/lib/python2.7/site-packages/flask/app.py", line 1477, in full_dispatch_request
    rv = self.handle_user_exception(e)
  File "/Users/zorba/anaconda2/lib/python2.7/site-packages/flask/app.py", line 1381, in handle_user_exception
    reraise(exc_type, exc_value, tb)
  File "/Users/zorba/anaconda2/lib/python2.7/site-packages/flask/app.py", line 1475, in full_dispatch_request
    rv = self.dispatch_request()
  File "/Users/zorba/anaconda2/lib/python2.7/site-packages/flask/app.py", line 1461, in dispatch_request
    return self.view_functions[rule.endpoint](**req.view_args)
  File "/Users/zorba/anaconda2/lib/python2.7/site-packages/psiturk/experiment.py", line 683, in regularpage
    return render_template(pagename)
  File "/Users/zorba/anaconda2/lib/python2.7/site-packages/flask/templating.py", line 127, in render_template
    return _render(ctx.app.jinja_env.get_or_select_template(template_name_or_list),
  File "/Users/zorba/anaconda2/lib/python2.7/site-packages/jinja2/environment.py", line 851, in get_or_select_template
    return self.get_template(template_name_or_list, parent, globals)
  File "/Users/zorba/anaconda2/lib/python2.7/site-packages/jinja2/environment.py", line 812, in get_template
    return self._load_template(name, self.make_globals(globals))
  File "/Users/zorba/anaconda2/lib/python2.7/site-packages/jinja2/environment.py", line 774, in _load_template
    cache_key = self.loader.get_source(self, name)[1]
  File "/Users/zorba/anaconda2/lib/python2.7/site-packages/flask/templating.py", line 64, in get_source
    raise TemplateNotFound(template)
TemplateNotFound: d
2016-12-02 22:00:56,598 Exception on /d [GET]
Traceback (most recent call last):
  File "/Users/zorba/anaconda2/lib/python2.7/site-packages/flask/app.py", line 1817, in wsgi_app
    response = self.full_dispatch_request()
  File "/Users/zorba/anaconda2/lib/python2.7/site-packages/flask/app.py", line 1477, in full_dispatch_request
    rv = self.handle_user_exception(e)
  File "/Users/zorba/anaconda2/lib/python2.7/site-packages/flask/app.py", line 1381, in handle_user_exception
    reraise(exc_type, exc_value, tb)
  File "/Users/zorba/anaconda2/lib/python2.7/site-packages/flask/app.py", line 1475, in full_dispatch_request
    rv = self.dispatch_request()
  File "/Users/zorba/anaconda2/lib/python2.7/site-packages/flask/app.py", line 1461, in dispatch_request
    return self.view_functions[rule.endpoint](**req.view_args)
  File "/Users/zorba/anaconda2/lib/python2.7/site-packages/psiturk/experiment.py", line 683, in regularpage
    return render_template(pagename)
  File "/Users/zorba/anaconda2/lib/python2.7/site-packages/flask/templating.py", line 127, in render_template
    return _render(ctx.app.jinja_env.get_or_select_template(template_name_or_list),
  File "/Users/zorba/anaconda2/lib/python2.7/site-packages/jinja2/environment.py", line 851, in get_or_select_template
    return self.get_template(template_name_or_list, parent, globals)
  File "/Users/zorba/anaconda2/lib/python2.7/site-packages/jinja2/environment.py", line 812, in get_template
    return self._load_template(name, self.make_globals(globals))
  File "/Users/zorba/anaconda2/lib/python2.7/site-packages/jinja2/environment.py", line 774, in _load_template
    cache_key = self.loader.get_source(self, name)[1]
  File "/Users/zorba/anaconda2/lib/python2.7/site-packages/flask/templating.py", line 64, in get_source
    raise TemplateNotFound(template)
TemplateNotFound: d
2016-12-02 22:01:38,308 Exception on /d [GET]
Traceback (most recent call last):
  File "/Users/zorba/anaconda2/lib/python2.7/site-packages/flask/app.py", line 1817, in wsgi_app
    response = self.full_dispatch_request()
  File "/Users/zorba/anaconda2/lib/python2.7/site-packages/flask/app.py", line 1477, in full_dispatch_request
    rv = self.handle_user_exception(e)
  File "/Users/zorba/anaconda2/lib/python2.7/site-packages/flask/app.py", line 1381, in handle_user_exception
    reraise(exc_type, exc_value, tb)
  File "/Users/zorba/anaconda2/lib/python2.7/site-packages/flask/app.py", line 1475, in full_dispatch_request
    rv = self.dispatch_request()
  File "/Users/zorba/anaconda2/lib/python2.7/site-packages/flask/app.py", line 1461, in dispatch_request
    return self.view_functions[rule.endpoint](**req.view_args)
  File "/Users/zorba/anaconda2/lib/python2.7/site-packages/psiturk/experiment.py", line 683, in regularpage
    return render_template(pagename)
  File "/Users/zorba/anaconda2/lib/python2.7/site-packages/flask/templating.py", line 127, in render_template
    return _render(ctx.app.jinja_env.get_or_select_template(template_name_or_list),
  File "/Users/zorba/anaconda2/lib/python2.7/site-packages/jinja2/environment.py", line 851, in get_or_select_template
    return self.get_template(template_name_or_list, parent, globals)
  File "/Users/zorba/anaconda2/lib/python2.7/site-packages/jinja2/environment.py", line 812, in get_template
    return self._load_template(name, self.make_globals(globals))
  File "/Users/zorba/anaconda2/lib/python2.7/site-packages/jinja2/environment.py", line 774, in _load_template
    cache_key = self.loader.get_source(self, name)[1]
  File "/Users/zorba/anaconda2/lib/python2.7/site-packages/flask/templating.py", line 64, in get_source
    raise TemplateNotFound(template)
TemplateNotFound: d
[2016-12-05 18:54:23 -0500] [45630] [CRITICAL] WORKER TIMEOUT (pid:45634)
[2016-12-05 18:54:23 -0500] [45630] [CRITICAL] WORKER TIMEOUT (pid:45635)
[2016-12-05 18:54:23 -0500] [45630] [CRITICAL] WORKER TIMEOUT (pid:45636)
[2016-12-05 18:54:23 -0500] [45630] [CRITICAL] WORKER TIMEOUT (pid:45637)
[2016-12-05 18:54:23 -0500] [45630] [CRITICAL] WORKER TIMEOUT (pid:45638)
[2016-12-05 18:54:23 -0500] [45630] [CRITICAL] WORKER TIMEOUT (pid:45639)
[2016-12-05 18:54:23 -0500] [45630] [CRITICAL] WORKER TIMEOUT (pid:45640)
[2016-12-05 18:54:23 -0500] [45630] [CRITICAL] WORKER TIMEOUT (pid:45641)
[2016-12-05 18:54:23 -0500] [45630] [CRITICAL] WORKER TIMEOUT (pid:45642)
[2016-12-05 19:45:51 -0500] [45934] [CRITICAL] WORKER TIMEOUT (pid:45938)
[2016-12-05 19:45:51 -0500] [45934] [CRITICAL] WORKER TIMEOUT (pid:45939)
[2016-12-05 19:45:51 -0500] [45934] [CRITICAL] WORKER TIMEOUT (pid:45940)
[2016-12-05 19:45:51 -0500] [45934] [CRITICAL] WORKER TIMEOUT (pid:45941)
[2016-12-05 19:45:51 -0500] [45934] [CRITICAL] WORKER TIMEOUT (pid:45942)
[2016-12-05 19:45:51 -0500] [45934] [CRITICAL] WORKER TIMEOUT (pid:45943)
[2016-12-05 19:45:51 -0500] [45934] [CRITICAL] WORKER TIMEOUT (pid:45944)
[2016-12-05 19:45:51 -0500] [45934] [CRITICAL] WORKER TIMEOUT (pid:45945)
[2016-12-05 19:45:51 -0500] [45934] [CRITICAL] WORKER TIMEOUT (pid:45946)
[2016-12-05 20:07:06 -0500] [45934] [CRITICAL] WORKER TIMEOUT (pid:45984)
[2016-12-05 20:07:06 -0500] [45934] [CRITICAL] WORKER TIMEOUT (pid:45985)
[2016-12-05 20:07:06 -0500] [45934] [CRITICAL] WORKER TIMEOUT (pid:45986)
[2016-12-05 20:07:06 -0500] [45934] [CRITICAL] WORKER TIMEOUT (pid:45987)
[2016-12-05 20:07:06 -0500] [45934] [CRITICAL] WORKER TIMEOUT (pid:45988)
[2016-12-05 20:07:06 -0500] [45934] [CRITICAL] WORKER TIMEOUT (pid:45989)
[2016-12-05 20:07:06 -0500] [45934] [CRITICAL] WORKER TIMEOUT (pid:45981)
[2016-12-05 20:07:06 -0500] [45934] [CRITICAL] WORKER TIMEOUT (pid:45982)
[2016-12-05 20:07:06 -0500] [45934] [CRITICAL] WORKER TIMEOUT (pid:45983)
[2016-12-05 20:09:46 -0500] [45934] [CRITICAL] WORKER TIMEOUT (pid:46034)
[2016-12-05 20:09:46 -0500] [45934] [CRITICAL] WORKER TIMEOUT (pid:46035)
[2016-12-05 20:09:46 -0500] [45934] [CRITICAL] WORKER TIMEOUT (pid:46036)
[2016-12-05 20:09:46 -0500] [45934] [CRITICAL] WORKER TIMEOUT (pid:46037)
[2016-12-05 20:09:46 -0500] [45934] [CRITICAL] WORKER TIMEOUT (pid:46038)
[2016-12-05 20:09:46 -0500] [45934] [CRITICAL] WORKER TIMEOUT (pid:46039)
[2016-12-05 20:09:46 -0500] [45934] [CRITICAL] WORKER TIMEOUT (pid:46040)
[2016-12-05 20:09:46 -0500] [45934] [CRITICAL] WORKER TIMEOUT (pid:46041)
[2016-12-05 20:09:46 -0500] [45934] [CRITICAL] WORKER TIMEOUT (pid:46042)
[2016-12-06 00:19:16 -0500] [46561] [ERROR] Exception in worker process
Traceback (most recent call last):
  File "/Users/zorba/anaconda2/lib/python2.7/site-packages/gunicorn/arbiter.py", line 557, in spawn_worker
    worker.init_process()
  File "/Users/zorba/anaconda2/lib/python2.7/site-packages/gunicorn/workers/base.py", line 126, in init_process
    self.load_wsgi()
  File "/Users/zorba/anaconda2/lib/python2.7/site-packages/gunicorn/workers/base.py", line 136, in load_wsgi
    self.wsgi = self.app.wsgi()
  File "/Users/zorba/anaconda2/lib/python2.7/site-packages/gunicorn/app/base.py", line 67, in wsgi
    self.callable = self.load()
  File "/Users/zorba/anaconda2/lib/python2.7/site-packages/psiturk/experiment_server.py", line 47, in load
    return util.import_app("psiturk.experiment:app")
  File "/Users/zorba/anaconda2/lib/python2.7/site-packages/gunicorn/util.py", line 357, in import_app
    __import__(module)
  File "/Users/zorba/anaconda2/lib/python2.7/site-packages/psiturk/experiment.py", line 72, in <module>
    from custom import custom_code
  File "/Users/zorba/Dropbox/Neuro/psiturk/Swaps-no-fix/custom.py", line 29, in <module>
    all_trials = load(f)
  File "/Users/zorba/anaconda2/lib/python2.7/pickle.py", line 1384, in load
    return Unpickler(file).load()
  File "/Users/zorba/anaconda2/lib/python2.7/pickle.py", line 864, in load
    dispatch[key](self)
  File "/Users/zorba/anaconda2/lib/python2.7/pickle.py", line 886, in load_eof
    raise EOFError
EOFError
[2016-12-06 00:19:16 -0500] [46562] [ERROR] Exception in worker process
Traceback (most recent call last):
  File "/Users/zorba/anaconda2/lib/python2.7/site-packages/gunicorn/arbiter.py", line 557, in spawn_worker
    worker.init_process()
  File "/Users/zorba/anaconda2/lib/python2.7/site-packages/gunicorn/workers/base.py", line 126, in init_process
    self.load_wsgi()
  File "/Users/zorba/anaconda2/lib/python2.7/site-packages/gunicorn/workers/base.py", line 136, in load_wsgi
    self.wsgi = self.app.wsgi()
  File "/Users/zorba/anaconda2/lib/python2.7/site-packages/gunicorn/app/base.py", line 67, in wsgi
    self.callable = self.load()
  File "/Users/zorba/anaconda2/lib/python2.7/site-packages/psiturk/experiment_server.py", line 47, in load
    return util.import_app("psiturk.experiment:app")
  File "/Users/zorba/anaconda2/lib/python2.7/site-packages/gunicorn/util.py", line 357, in import_app
    __import__(module)
  File "/Users/zorba/anaconda2/lib/python2.7/site-packages/psiturk/experiment.py", line 72, in <module>
    from custom import custom_code
  File "/Users/zorba/Dropbox/Neuro/psiturk/Swaps-no-fix/custom.py", line 29, in <module>
    all_trials = load(f)
  File "/Users/zorba/anaconda2/lib/python2.7/pickle.py", line 1384, in load
    return Unpickler(file).load()
  File "/Users/zorba/anaconda2/lib/python2.7/pickle.py", line 864, in load
    dispatch[key](self)
  File "/Users/zorba/anaconda2/lib/python2.7/pickle.py", line 886, in load_eof
    raise EOFError
EOFError
[2016-12-06 00:19:16 -0500] [46563] [ERROR] Exception in worker process
Traceback (most recent call last):
  File "/Users/zorba/anaconda2/lib/python2.7/site-packages/gunicorn/arbiter.py", line 557, in spawn_worker
    worker.init_process()
  File "/Users/zorba/anaconda2/lib/python2.7/site-packages/gunicorn/workers/base.py", line 126, in init_process
    self.load_wsgi()
  File "/Users/zorba/anaconda2/lib/python2.7/site-packages/gunicorn/workers/base.py", line 136, in load_wsgi
    self.wsgi = self.app.wsgi()
  File "/Users/zorba/anaconda2/lib/python2.7/site-packages/gunicorn/app/base.py", line 67, in wsgi
    self.callable = self.load()
  File "/Users/zorba/anaconda2/lib/python2.7/site-packages/psiturk/experiment_server.py", line 47, in load
    return util.import_app("psiturk.experiment:app")
  File "/Users/zorba/anaconda2/lib/python2.7/site-packages/gunicorn/util.py", line 357, in import_app
    __import__(module)
  File "/Users/zorba/anaconda2/lib/python2.7/site-packages/psiturk/experiment.py", line 72, in <module>
    from custom import custom_code
  File "/Users/zorba/Dropbox/Neuro/psiturk/Swaps-no-fix/custom.py", line 29, in <module>
    all_trials = load(f)
  File "/Users/zorba/anaconda2/lib/python2.7/pickle.py", line 1384, in load
    return Unpickler(file).load()
  File "/Users/zorba/anaconda2/lib/python2.7/pickle.py", line 864, in load
    dispatch[key](self)
  File "/Users/zorba/anaconda2/lib/python2.7/pickle.py", line 886, in load_eof
    raise EOFError
EOFError
[2016-12-06 00:19:16 -0500] [46565] [ERROR] Exception in worker process
Traceback (most recent call last):
  File "/Users/zorba/anaconda2/lib/python2.7/site-packages/gunicorn/arbiter.py", line 557, in spawn_worker
    worker.init_process()
  File "/Users/zorba/anaconda2/lib/python2.7/site-packages/gunicorn/workers/base.py", line 126, in init_process
    self.load_wsgi()
  File "/Users/zorba/anaconda2/lib/python2.7/site-packages/gunicorn/workers/base.py", line 136, in load_wsgi
    self.wsgi = self.app.wsgi()
  File "/Users/zorba/anaconda2/lib/python2.7/site-packages/gunicorn/app/base.py", line 67, in wsgi
    self.callable = self.load()
  File "/Users/zorba/anaconda2/lib/python2.7/site-packages/psiturk/experiment_server.py", line 47, in load
    return util.import_app("psiturk.experiment:app")
  File "/Users/zorba/anaconda2/lib/python2.7/site-packages/gunicorn/util.py", line 357, in import_app
    __import__(module)
  File "/Users/zorba/anaconda2/lib/python2.7/site-packages/psiturk/experiment.py", line 72, in <module>
    from custom import custom_code
  File "/Users/zorba/Dropbox/Neuro/psiturk/Swaps-no-fix/custom.py", line 29, in <module>
    all_trials = load(f)
  File "/Users/zorba/anaconda2/lib/python2.7/pickle.py", line 1384, in load
    return Unpickler(file).load()
  File "/Users/zorba/anaconda2/lib/python2.7/pickle.py", line 864, in load
    dispatch[key](self)
  File "/Users/zorba/anaconda2/lib/python2.7/pickle.py", line 886, in load_eof
    raise EOFError
EOFError
[2016-12-06 00:19:16 -0500] [46566] [ERROR] Exception in worker process
Traceback (most recent call last):
  File "/Users/zorba/anaconda2/lib/python2.7/site-packages/gunicorn/arbiter.py", line 557, in spawn_worker
    worker.init_process()
  File "/Users/zorba/anaconda2/lib/python2.7/site-packages/gunicorn/workers/base.py", line 126, in init_process
    self.load_wsgi()
  File "/Users/zorba/anaconda2/lib/python2.7/site-packages/gunicorn/workers/base.py", line 136, in load_wsgi
    self.wsgi = self.app.wsgi()
  File "/Users/zorba/anaconda2/lib/python2.7/site-packages/gunicorn/app/base.py", line 67, in wsgi
    self.callable = self.load()
  File "/Users/zorba/anaconda2/lib/python2.7/site-packages/psiturk/experiment_server.py", line 47, in load
    return util.import_app("psiturk.experiment:app")
  File "/Users/zorba/anaconda2/lib/python2.7/site-packages/gunicorn/util.py", line 357, in import_app
    __import__(module)
  File "/Users/zorba/anaconda2/lib/python2.7/site-packages/psiturk/experiment.py", line 72, in <module>
    from custom import custom_code
  File "/Users/zorba/Dropbox/Neuro/psiturk/Swaps-no-fix/custom.py", line 29, in <module>
    all_trials = load(f)
  File "/Users/zorba/anaconda2/lib/python2.7/pickle.py", line 1384, in load
    return Unpickler(file).load()
  File "/Users/zorba/anaconda2/lib/python2.7/pickle.py", line 864, in load
    dispatch[key](self)
  File "/Users/zorba/anaconda2/lib/python2.7/pickle.py", line 886, in load_eof
    raise EOFError
EOFError
[2016-12-06 00:19:16 -0500] [46564] [ERROR] Exception in worker process
Traceback (most recent call last):
  File "/Users/zorba/anaconda2/lib/python2.7/site-packages/gunicorn/arbiter.py", line 557, in spawn_worker
    worker.init_process()
  File "/Users/zorba/anaconda2/lib/python2.7/site-packages/gunicorn/workers/base.py", line 126, in init_process
    self.load_wsgi()
  File "/Users/zorba/anaconda2/lib/python2.7/site-packages/gunicorn/workers/base.py", line 136, in load_wsgi
    self.wsgi = self.app.wsgi()
  File "/Users/zorba/anaconda2/lib/python2.7/site-packages/gunicorn/app/base.py", line 67, in wsgi
    self.callable = self.load()
  File "/Users/zorba/anaconda2/lib/python2.7/site-packages/psiturk/experiment_server.py", line 47, in load
    return util.import_app("psiturk.experiment:app")
  File "/Users/zorba/anaconda2/lib/python2.7/site-packages/gunicorn/util.py", line 357, in import_app
    __import__(module)
  File "/Users/zorba/anaconda2/lib/python2.7/site-packages/psiturk/experiment.py", line 72, in <module>
    from custom import custom_code
  File "/Users/zorba/Dropbox/Neuro/psiturk/Swaps-no-fix/custom.py", line 29, in <module>
    all_trials = load(f)
  File "/Users/zorba/anaconda2/lib/python2.7/pickle.py", line 1384, in load
    return Unpickler(file).load()
  File "/Users/zorba/anaconda2/lib/python2.7/pickle.py", line 864, in load
    dispatch[key](self)
  File "/Users/zorba/anaconda2/lib/python2.7/pickle.py", line 886, in load_eof
    raise EOFError
EOFError
[2016-12-06 00:19:16 -0500] [46568] [ERROR] Exception in worker process
Traceback (most recent call last):
  File "/Users/zorba/anaconda2/lib/python2.7/site-packages/gunicorn/arbiter.py", line 557, in spawn_worker
    worker.init_process()
  File "/Users/zorba/anaconda2/lib/python2.7/site-packages/gunicorn/workers/base.py", line 126, in init_process
    self.load_wsgi()
  File "/Users/zorba/anaconda2/lib/python2.7/site-packages/gunicorn/workers/base.py", line 136, in load_wsgi
    self.wsgi = self.app.wsgi()
  File "/Users/zorba/anaconda2/lib/python2.7/site-packages/gunicorn/app/base.py", line 67, in wsgi
    self.callable = self.load()
  File "/Users/zorba/anaconda2/lib/python2.7/site-packages/psiturk/experiment_server.py", line 47, in load
    return util.import_app("psiturk.experiment:app")
  File "/Users/zorba/anaconda2/lib/python2.7/site-packages/gunicorn/util.py", line 357, in import_app
    __import__(module)
  File "/Users/zorba/anaconda2/lib/python2.7/site-packages/psiturk/experiment.py", line 72, in <module>
    from custom import custom_code
  File "/Users/zorba/Dropbox/Neuro/psiturk/Swaps-no-fix/custom.py", line 29, in <module>
    all_trials = load(f)
  File "/Users/zorba/anaconda2/lib/python2.7/pickle.py", line 1384, in load
    return Unpickler(file).load()
  File "/Users/zorba/anaconda2/lib/python2.7/pickle.py", line 864, in load
    dispatch[key](self)
  File "/Users/zorba/anaconda2/lib/python2.7/pickle.py", line 886, in load_eof
    raise EOFError
EOFError
[2016-12-06 00:19:16 -0500] [46567] [ERROR] Exception in worker process
Traceback (most recent call last):
  File "/Users/zorba/anaconda2/lib/python2.7/site-packages/gunicorn/arbiter.py", line 557, in spawn_worker
    worker.init_process()
  File "/Users/zorba/anaconda2/lib/python2.7/site-packages/gunicorn/workers/base.py", line 126, in init_process
    self.load_wsgi()
  File "/Users/zorba/anaconda2/lib/python2.7/site-packages/gunicorn/workers/base.py", line 136, in load_wsgi
    self.wsgi = self.app.wsgi()
  File "/Users/zorba/anaconda2/lib/python2.7/site-packages/gunicorn/app/base.py", line 67, in wsgi
    self.callable = self.load()
  File "/Users/zorba/anaconda2/lib/python2.7/site-packages/psiturk/experiment_server.py", line 47, in load
    return util.import_app("psiturk.experiment:app")
  File "/Users/zorba/anaconda2/lib/python2.7/site-packages/gunicorn/util.py", line 357, in import_app
    __import__(module)
  File "/Users/zorba/anaconda2/lib/python2.7/site-packages/psiturk/experiment.py", line 72, in <module>
    from custom import custom_code
  File "/Users/zorba/Dropbox/Neuro/psiturk/Swaps-no-fix/custom.py", line 29, in <module>
    all_trials = load(f)
  File "/Users/zorba/anaconda2/lib/python2.7/pickle.py", line 1384, in load
    return Unpickler(file).load()
  File "/Users/zorba/anaconda2/lib/python2.7/pickle.py", line 864, in load
    dispatch[key](self)
  File "/Users/zorba/anaconda2/lib/python2.7/pickle.py", line 886, in load_eof
    raise EOFError
EOFError
[2016-12-06 00:19:16 -0500] [46569] [ERROR] Exception in worker process
Traceback (most recent call last):
  File "/Users/zorba/anaconda2/lib/python2.7/site-packages/gunicorn/arbiter.py", line 557, in spawn_worker
    worker.init_process()
  File "/Users/zorba/anaconda2/lib/python2.7/site-packages/gunicorn/workers/base.py", line 126, in init_process
    self.load_wsgi()
  File "/Users/zorba/anaconda2/lib/python2.7/site-packages/gunicorn/workers/base.py", line 136, in load_wsgi
    self.wsgi = self.app.wsgi()
  File "/Users/zorba/anaconda2/lib/python2.7/site-packages/gunicorn/app/base.py", line 67, in wsgi
    self.callable = self.load()
  File "/Users/zorba/anaconda2/lib/python2.7/site-packages/psiturk/experiment_server.py", line 47, in load
    return util.import_app("psiturk.experiment:app")
  File "/Users/zorba/anaconda2/lib/python2.7/site-packages/gunicorn/util.py", line 357, in import_app
    __import__(module)
  File "/Users/zorba/anaconda2/lib/python2.7/site-packages/psiturk/experiment.py", line 72, in <module>
    from custom import custom_code
  File "/Users/zorba/Dropbox/Neuro/psiturk/Swaps-no-fix/custom.py", line 29, in <module>
    all_trials = load(f)
  File "/Users/zorba/anaconda2/lib/python2.7/pickle.py", line 1384, in load
    return Unpickler(file).load()
  File "/Users/zorba/anaconda2/lib/python2.7/pickle.py", line 864, in load
    dispatch[key](self)
  File "/Users/zorba/anaconda2/lib/python2.7/pickle.py", line 886, in load_eof
    raise EOFError
EOFError
[2016-12-06 00:19:59 -0500] [46641] [ERROR] Exception in worker process
Traceback (most recent call last):
  File "/Users/zorba/anaconda2/lib/python2.7/site-packages/gunicorn/arbiter.py", line 557, in spawn_worker
    worker.init_process()
  File "/Users/zorba/anaconda2/lib/python2.7/site-packages/gunicorn/workers/base.py", line 126, in init_process
    self.load_wsgi()
  File "/Users/zorba/anaconda2/lib/python2.7/site-packages/gunicorn/workers/base.py", line 136, in load_wsgi
    self.wsgi = self.app.wsgi()
  File "/Users/zorba/anaconda2/lib/python2.7/site-packages/gunicorn/app/base.py", line 67, in wsgi
    self.callable = self.load()
  File "/Users/zorba/anaconda2/lib/python2.7/site-packages/psiturk/experiment_server.py", line 47, in load
    return util.import_app("psiturk.experiment:app")
  File "/Users/zorba/anaconda2/lib/python2.7/site-packages/gunicorn/util.py", line 357, in import_app
    __import__(module)
  File "/Users/zorba/anaconda2/lib/python2.7/site-packages/psiturk/experiment.py", line 72, in <module>
    from custom import custom_code
  File "/Users/zorba/Dropbox/Neuro/psiturk/Swaps-no-fix/custom.py", line 29, in <module>
    all_trials = load(f)
  File "/Users/zorba/anaconda2/lib/python2.7/pickle.py", line 1384, in load
    return Unpickler(file).load()
  File "/Users/zorba/anaconda2/lib/python2.7/pickle.py", line 864, in load
    dispatch[key](self)
  File "/Users/zorba/anaconda2/lib/python2.7/pickle.py", line 886, in load_eof
    raise EOFError
EOFError
[2016-12-06 00:19:59 -0500] [46642] [ERROR] Exception in worker process
Traceback (most recent call last):
  File "/Users/zorba/anaconda2/lib/python2.7/site-packages/gunicorn/arbiter.py", line 557, in spawn_worker
    worker.init_process()
  File "/Users/zorba/anaconda2/lib/python2.7/site-packages/gunicorn/workers/base.py", line 126, in init_process
    self.load_wsgi()
  File "/Users/zorba/anaconda2/lib/python2.7/site-packages/gunicorn/workers/base.py", line 136, in load_wsgi
    self.wsgi = self.app.wsgi()
  File "/Users/zorba/anaconda2/lib/python2.7/site-packages/gunicorn/app/base.py", line 67, in wsgi
    self.callable = self.load()
  File "/Users/zorba/anaconda2/lib/python2.7/site-packages/psiturk/experiment_server.py", line 47, in load
    return util.import_app("psiturk.experiment:app")
  File "/Users/zorba/anaconda2/lib/python2.7/site-packages/gunicorn/util.py", line 357, in import_app
    __import__(module)
  File "/Users/zorba/anaconda2/lib/python2.7/site-packages/psiturk/experiment.py", line 72, in <module>
    from custom import custom_code
  File "/Users/zorba/Dropbox/Neuro/psiturk/Swaps-no-fix/custom.py", line 29, in <module>
    all_trials = load(f)
  File "/Users/zorba/anaconda2/lib/python2.7/pickle.py", line 1384, in load
    return Unpickler(file).load()
  File "/Users/zorba/anaconda2/lib/python2.7/pickle.py", line 864, in load
    dispatch[key](self)
  File "/Users/zorba/anaconda2/lib/python2.7/pickle.py", line 886, in load_eof
    raise EOFError
EOFError
[2016-12-06 00:20:00 -0500] [46643] [ERROR] Exception in worker process
Traceback (most recent call last):
  File "/Users/zorba/anaconda2/lib/python2.7/site-packages/gunicorn/arbiter.py", line 557, in spawn_worker
    worker.init_process()
  File "/Users/zorba/anaconda2/lib/python2.7/site-packages/gunicorn/workers/base.py", line 126, in init_process
    self.load_wsgi()
  File "/Users/zorba/anaconda2/lib/python2.7/site-packages/gunicorn/workers/base.py", line 136, in load_wsgi
    self.wsgi = self.app.wsgi()
  File "/Users/zorba/anaconda2/lib/python2.7/site-packages/gunicorn/app/base.py", line 67, in wsgi
    self.callable = self.load()
  File "/Users/zorba/anaconda2/lib/python2.7/site-packages/psiturk/experiment_server.py", line 47, in load
    return util.import_app("psiturk.experiment:app")
  File "/Users/zorba/anaconda2/lib/python2.7/site-packages/gunicorn/util.py", line 357, in import_app
    __import__(module)
  File "/Users/zorba/anaconda2/lib/python2.7/site-packages/psiturk/experiment.py", line 72, in <module>
    from custom import custom_code
  File "/Users/zorba/Dropbox/Neuro/psiturk/Swaps-no-fix/custom.py", line 29, in <module>
    all_trials = load(f)
  File "/Users/zorba/anaconda2/lib/python2.7/pickle.py", line 1384, in load
    return Unpickler(file).load()
  File "/Users/zorba/anaconda2/lib/python2.7/pickle.py", line 864, in load
    dispatch[key](self)
  File "/Users/zorba/anaconda2/lib/python2.7/pickle.py", line 886, in load_eof
    raise EOFError
EOFError
[2016-12-06 00:20:00 -0500] [46644] [ERROR] Exception in worker process
Traceback (most recent call last):
  File "/Users/zorba/anaconda2/lib/python2.7/site-packages/gunicorn/arbiter.py", line 557, in spawn_worker
    worker.init_process()
  File "/Users/zorba/anaconda2/lib/python2.7/site-packages/gunicorn/workers/base.py", line 126, in init_process
    self.load_wsgi()
  File "/Users/zorba/anaconda2/lib/python2.7/site-packages/gunicorn/workers/base.py", line 136, in load_wsgi
    self.wsgi = self.app.wsgi()
  File "/Users/zorba/anaconda2/lib/python2.7/site-packages/gunicorn/app/base.py", line 67, in wsgi
    self.callable = self.load()
  File "/Users/zorba/anaconda2/lib/python2.7/site-packages/psiturk/experiment_server.py", line 47, in load
    return util.import_app("psiturk.experiment:app")
  File "/Users/zorba/anaconda2/lib/python2.7/site-packages/gunicorn/util.py", line 357, in import_app
    __import__(module)
  File "/Users/zorba/anaconda2/lib/python2.7/site-packages/psiturk/experiment.py", line 72, in <module>
    from custom import custom_code
  File "/Users/zorba/Dropbox/Neuro/psiturk/Swaps-no-fix/custom.py", line 29, in <module>
    all_trials = load(f)
  File "/Users/zorba/anaconda2/lib/python2.7/pickle.py", line 1384, in load
    return Unpickler(file).load()
  File "/Users/zorba/anaconda2/lib/python2.7/pickle.py", line 864, in load
    dispatch[key](self)
  File "/Users/zorba/anaconda2/lib/python2.7/pickle.py", line 886, in load_eof
    raise EOFError
EOFError
[2016-12-06 00:20:00 -0500] [46645] [ERROR] Exception in worker process
Traceback (most recent call last):
  File "/Users/zorba/anaconda2/lib/python2.7/site-packages/gunicorn/arbiter.py", line 557, in spawn_worker
    worker.init_process()
  File "/Users/zorba/anaconda2/lib/python2.7/site-packages/gunicorn/workers/base.py", line 126, in init_process
    self.load_wsgi()
  File "/Users/zorba/anaconda2/lib/python2.7/site-packages/gunicorn/workers/base.py", line 136, in load_wsgi
    self.wsgi = self.app.wsgi()
  File "/Users/zorba/anaconda2/lib/python2.7/site-packages/gunicorn/app/base.py", line 67, in wsgi
    self.callable = self.load()
  File "/Users/zorba/anaconda2/lib/python2.7/site-packages/psiturk/experiment_server.py", line 47, in load
    return util.import_app("psiturk.experiment:app")
  File "/Users/zorba/anaconda2/lib/python2.7/site-packages/gunicorn/util.py", line 357, in import_app
    __import__(module)
  File "/Users/zorba/anaconda2/lib/python2.7/site-packages/psiturk/experiment.py", line 72, in <module>
    from custom import custom_code
  File "/Users/zorba/Dropbox/Neuro/psiturk/Swaps-no-fix/custom.py", line 29, in <module>
    all_trials = load(f)
  File "/Users/zorba/anaconda2/lib/python2.7/pickle.py", line 1384, in load
    return Unpickler(file).load()
  File "/Users/zorba/anaconda2/lib/python2.7/pickle.py", line 864, in load
    dispatch[key](self)
  File "/Users/zorba/anaconda2/lib/python2.7/pickle.py", line 886, in load_eof
    raise EOFError
EOFError
[2016-12-06 00:20:00 -0500] [46646] [ERROR] Exception in worker process
Traceback (most recent call last):
  File "/Users/zorba/anaconda2/lib/python2.7/site-packages/gunicorn/arbiter.py", line 557, in spawn_worker
    worker.init_process()
  File "/Users/zorba/anaconda2/lib/python2.7/site-packages/gunicorn/workers/base.py", line 126, in init_process
    self.load_wsgi()
  File "/Users/zorba/anaconda2/lib/python2.7/site-packages/gunicorn/workers/base.py", line 136, in load_wsgi
    self.wsgi = self.app.wsgi()
  File "/Users/zorba/anaconda2/lib/python2.7/site-packages/gunicorn/app/base.py", line 67, in wsgi
    self.callable = self.load()
  File "/Users/zorba/anaconda2/lib/python2.7/site-packages/psiturk/experiment_server.py", line 47, in load
    return util.import_app("psiturk.experiment:app")
  File "/Users/zorba/anaconda2/lib/python2.7/site-packages/gunicorn/util.py", line 357, in import_app
    __import__(module)
  File "/Users/zorba/anaconda2/lib/python2.7/site-packages/psiturk/experiment.py", line 72, in <module>
    from custom import custom_code
  File "/Users/zorba/Dropbox/Neuro/psiturk/Swaps-no-fix/custom.py", line 29, in <module>
    all_trials = load(f)
  File "/Users/zorba/anaconda2/lib/python2.7/pickle.py", line 1384, in load
    return Unpickler(file).load()
  File "/Users/zorba/anaconda2/lib/python2.7/pickle.py", line 864, in load
    dispatch[key](self)
  File "/Users/zorba/anaconda2/lib/python2.7/pickle.py", line 886, in load_eof
    raise EOFError
EOFError
[2016-12-06 00:20:00 -0500] [46647] [ERROR] Exception in worker process
Traceback (most recent call last):
  File "/Users/zorba/anaconda2/lib/python2.7/site-packages/gunicorn/arbiter.py", line 557, in spawn_worker
    worker.init_process()
  File "/Users/zorba/anaconda2/lib/python2.7/site-packages/gunicorn/workers/base.py", line 126, in init_process
    self.load_wsgi()
  File "/Users/zorba/anaconda2/lib/python2.7/site-packages/gunicorn/workers/base.py", line 136, in load_wsgi
    self.wsgi = self.app.wsgi()
  File "/Users/zorba/anaconda2/lib/python2.7/site-packages/gunicorn/app/base.py", line 67, in wsgi
    self.callable = self.load()
  File "/Users/zorba/anaconda2/lib/python2.7/site-packages/psiturk/experiment_server.py", line 47, in load
    return util.import_app("psiturk.experiment:app")
  File "/Users/zorba/anaconda2/lib/python2.7/site-packages/gunicorn/util.py", line 357, in import_app
    __import__(module)
  File "/Users/zorba/anaconda2/lib/python2.7/site-packages/psiturk/experiment.py", line 72, in <module>
    from custom import custom_code
  File "/Users/zorba/Dropbox/Neuro/psiturk/Swaps-no-fix/custom.py", line 29, in <module>
    all_trials = load(f)
  File "/Users/zorba/anaconda2/lib/python2.7/pickle.py", line 1384, in load
    return Unpickler(file).load()
  File "/Users/zorba/anaconda2/lib/python2.7/pickle.py", line 864, in load
    dispatch[key](self)
  File "/Users/zorba/anaconda2/lib/python2.7/pickle.py", line 886, in load_eof
    raise EOFError
EOFError
[2016-12-06 00:20:00 -0500] [46648] [ERROR] Exception in worker process
Traceback (most recent call last):
  File "/Users/zorba/anaconda2/lib/python2.7/site-packages/gunicorn/arbiter.py", line 557, in spawn_worker
    worker.init_process()
  File "/Users/zorba/anaconda2/lib/python2.7/site-packages/gunicorn/workers/base.py", line 126, in init_process
    self.load_wsgi()
  File "/Users/zorba/anaconda2/lib/python2.7/site-packages/gunicorn/workers/base.py", line 136, in load_wsgi
    self.wsgi = self.app.wsgi()
  File "/Users/zorba/anaconda2/lib/python2.7/site-packages/gunicorn/app/base.py", line 67, in wsgi
    self.callable = self.load()
  File "/Users/zorba/anaconda2/lib/python2.7/site-packages/psiturk/experiment_server.py", line 47, in load
    return util.import_app("psiturk.experiment:app")
  File "/Users/zorba/anaconda2/lib/python2.7/site-packages/gunicorn/util.py", line 357, in import_app
    __import__(module)
  File "/Users/zorba/anaconda2/lib/python2.7/site-packages/psiturk/experiment.py", line 72, in <module>
    from custom import custom_code
  File "/Users/zorba/Dropbox/Neuro/psiturk/Swaps-no-fix/custom.py", line 29, in <module>
    all_trials = load(f)
  File "/Users/zorba/anaconda2/lib/python2.7/pickle.py", line 1384, in load
    return Unpickler(file).load()
  File "/Users/zorba/anaconda2/lib/python2.7/pickle.py", line 864, in load
    dispatch[key](self)
  File "/Users/zorba/anaconda2/lib/python2.7/pickle.py", line 886, in load_eof
    raise EOFError
EOFError
[2016-12-06 00:20:00 -0500] [46649] [ERROR] Exception in worker process
Traceback (most recent call last):
  File "/Users/zorba/anaconda2/lib/python2.7/site-packages/gunicorn/arbiter.py", line 557, in spawn_worker
    worker.init_process()
  File "/Users/zorba/anaconda2/lib/python2.7/site-packages/gunicorn/workers/base.py", line 126, in init_process
    self.load_wsgi()
  File "/Users/zorba/anaconda2/lib/python2.7/site-packages/gunicorn/workers/base.py", line 136, in load_wsgi
    self.wsgi = self.app.wsgi()
  File "/Users/zorba/anaconda2/lib/python2.7/site-packages/gunicorn/app/base.py", line 67, in wsgi
    self.callable = self.load()
  File "/Users/zorba/anaconda2/lib/python2.7/site-packages/psiturk/experiment_server.py", line 47, in load
    return util.import_app("psiturk.experiment:app")
  File "/Users/zorba/anaconda2/lib/python2.7/site-packages/gunicorn/util.py", line 357, in import_app
    __import__(module)
  File "/Users/zorba/anaconda2/lib/python2.7/site-packages/psiturk/experiment.py", line 72, in <module>
    from custom import custom_code
  File "/Users/zorba/Dropbox/Neuro/psiturk/Swaps-no-fix/custom.py", line 29, in <module>
    all_trials = load(f)
  File "/Users/zorba/anaconda2/lib/python2.7/pickle.py", line 1384, in load
    return Unpickler(file).load()
  File "/Users/zorba/anaconda2/lib/python2.7/pickle.py", line 864, in load
    dispatch[key](self)
  File "/Users/zorba/anaconda2/lib/python2.7/pickle.py", line 886, in load_eof
    raise EOFError
EOFError
[2016-12-06 13:24:44 -0500] [47632] [CRITICAL] WORKER TIMEOUT (pid:47636)
[2016-12-06 13:24:44 -0500] [47632] [CRITICAL] WORKER TIMEOUT (pid:47637)
[2016-12-06 13:24:44 -0500] [47632] [CRITICAL] WORKER TIMEOUT (pid:47638)
[2016-12-06 13:24:44 -0500] [47632] [CRITICAL] WORKER TIMEOUT (pid:47639)
[2016-12-06 13:24:44 -0500] [47632] [CRITICAL] WORKER TIMEOUT (pid:47640)
[2016-12-06 13:24:44 -0500] [47632] [CRITICAL] WORKER TIMEOUT (pid:47641)
[2016-12-06 13:24:44 -0500] [47632] [CRITICAL] WORKER TIMEOUT (pid:47642)
[2016-12-06 13:24:44 -0500] [47632] [CRITICAL] WORKER TIMEOUT (pid:47643)
[2016-12-06 13:24:44 -0500] [47632] [CRITICAL] WORKER TIMEOUT (pid:47644)
[2016-12-06 14:07:21 -0500] [47632] [CRITICAL] WORKER TIMEOUT (pid:47755)
[2016-12-06 14:07:21 -0500] [47632] [CRITICAL] WORKER TIMEOUT (pid:47756)
[2016-12-06 14:07:21 -0500] [47632] [CRITICAL] WORKER TIMEOUT (pid:47757)
[2016-12-06 14:07:21 -0500] [47632] [CRITICAL] WORKER TIMEOUT (pid:47758)
[2016-12-06 14:07:21 -0500] [47632] [CRITICAL] WORKER TIMEOUT (pid:47759)
[2016-12-06 14:07:21 -0500] [47632] [CRITICAL] WORKER TIMEOUT (pid:47760)
[2016-12-06 14:07:21 -0500] [47632] [CRITICAL] WORKER TIMEOUT (pid:47761)
[2016-12-06 14:07:21 -0500] [47632] [CRITICAL] WORKER TIMEOUT (pid:47762)
[2016-12-06 14:07:21 -0500] [47632] [CRITICAL] WORKER TIMEOUT (pid:47763)
[2016-12-06 19:04:30 -0500] [49525] [CRITICAL] WORKER TIMEOUT (pid:49534)
[2016-12-06 19:04:34 -0500] [49525] [CRITICAL] WORKER TIMEOUT (pid:49536)
[2016-12-06 19:04:34 -0500] [49525] [CRITICAL] WORKER TIMEOUT (pid:49530)
[2016-12-06 19:04:34 -0500] [49525] [CRITICAL] WORKER TIMEOUT (pid:49532)
[2016-12-06 19:04:37 -0500] [49525] [CRITICAL] WORKER TIMEOUT (pid:49533)
[2016-12-06 19:04:38 -0500] [49525] [CRITICAL] WORKER TIMEOUT (pid:49537)
[2016-12-06 19:04:38 -0500] [49525] [CRITICAL] WORKER TIMEOUT (pid:49529)
[2016-12-06 19:04:38 -0500] [49525] [CRITICAL] WORKER TIMEOUT (pid:49531)
[2016-12-06 19:04:38 -0500] [49525] [CRITICAL] WORKER TIMEOUT (pid:49535)
[2016-12-06 20:18:24 -0500] [49740] [CRITICAL] WORKER TIMEOUT (pid:49744)
[2016-12-06 20:18:24 -0500] [49740] [CRITICAL] WORKER TIMEOUT (pid:49745)
[2016-12-06 20:18:24 -0500] [49740] [CRITICAL] WORKER TIMEOUT (pid:49746)
[2016-12-06 20:18:24 -0500] [49740] [CRITICAL] WORKER TIMEOUT (pid:49747)
[2016-12-06 20:18:24 -0500] [49740] [CRITICAL] WORKER TIMEOUT (pid:49748)
[2016-12-06 20:18:24 -0500] [49740] [CRITICAL] WORKER TIMEOUT (pid:49749)
[2016-12-06 20:18:24 -0500] [49740] [CRITICAL] WORKER TIMEOUT (pid:49750)
[2016-12-06 20:18:24 -0500] [49740] [CRITICAL] WORKER TIMEOUT (pid:49752)
[2016-12-06 21:26:01 -0500] [49740] [CRITICAL] WORKER TIMEOUT (pid:49782)
[2016-12-06 21:26:01 -0500] [49740] [CRITICAL] WORKER TIMEOUT (pid:49783)
[2016-12-06 21:26:01 -0500] [49740] [CRITICAL] WORKER TIMEOUT (pid:49751)
[2016-12-06 21:26:01 -0500] [49740] [CRITICAL] WORKER TIMEOUT (pid:49784)
[2016-12-06 21:26:01 -0500] [49740] [CRITICAL] WORKER TIMEOUT (pid:49785)
[2016-12-06 21:26:01 -0500] [49740] [CRITICAL] WORKER TIMEOUT (pid:49786)
[2016-12-06 21:26:01 -0500] [49740] [CRITICAL] WORKER TIMEOUT (pid:49787)
[2016-12-06 21:26:01 -0500] [49740] [CRITICAL] WORKER TIMEOUT (pid:49788)
[2016-12-06 21:26:01 -0500] [49740] [CRITICAL] WORKER TIMEOUT (pid:49781)
[2016-12-07 00:26:59 -0500] [49740] [CRITICAL] WORKER TIMEOUT (pid:49840)
[2016-12-07 00:26:59 -0500] [49740] [CRITICAL] WORKER TIMEOUT (pid:49841)
[2016-12-07 00:26:59 -0500] [49740] [CRITICAL] WORKER TIMEOUT (pid:49842)
[2016-12-07 00:26:59 -0500] [49740] [CRITICAL] WORKER TIMEOUT (pid:49843)
[2016-12-07 00:26:59 -0500] [49740] [CRITICAL] WORKER TIMEOUT (pid:49844)
[2016-12-07 00:26:59 -0500] [49740] [CRITICAL] WORKER TIMEOUT (pid:49845)
[2016-12-07 00:26:59 -0500] [49740] [CRITICAL] WORKER TIMEOUT (pid:49846)
[2016-12-07 00:26:59 -0500] [49740] [CRITICAL] WORKER TIMEOUT (pid:49847)
[2016-12-07 00:26:59 -0500] [49740] [CRITICAL] WORKER TIMEOUT (pid:49848)
[2016-12-07 09:27:42 -0500] [49740] [CRITICAL] WORKER TIMEOUT (pid:49859)
[2016-12-07 11:31:58 -0500] [49740] [CRITICAL] WORKER TIMEOUT (pid:49864)
[2016-12-07 12:58:36 -0500] [49740] [CRITICAL] WORKER TIMEOUT (pid:49856)
[2016-12-07 12:58:36 -0500] [49740] [CRITICAL] WORKER TIMEOUT (pid:49857)
[2016-12-07 12:58:36 -0500] [49740] [CRITICAL] WORKER TIMEOUT (pid:49858)
[2016-12-07 12:58:36 -0500] [49740] [CRITICAL] WORKER TIMEOUT (pid:49860)
[2016-12-07 12:58:36 -0500] [49740] [CRITICAL] WORKER TIMEOUT (pid:49861)
[2016-12-07 12:58:36 -0500] [49740] [CRITICAL] WORKER TIMEOUT (pid:50004)
[2016-12-07 12:58:36 -0500] [49740] [CRITICAL] WORKER TIMEOUT (pid:49853)
[2016-12-07 12:58:36 -0500] [49740] [CRITICAL] WORKER TIMEOUT (pid:49854)
[2016-12-07 12:58:36 -0500] [49740] [CRITICAL] WORKER TIMEOUT (pid:49855)
[2016-12-07 13:28:50 -0500] [49740] [CRITICAL] WORKER TIMEOUT (pid:50650)
[2016-12-07 21:34:15 -0500] [51906] [CRITICAL] WORKER TIMEOUT (pid:51910)
[2016-12-07 21:34:15 -0500] [51906] [CRITICAL] WORKER TIMEOUT (pid:51912)
[2016-12-07 21:34:15 -0500] [51906] [CRITICAL] WORKER TIMEOUT (pid:51913)
[2016-12-07 21:34:15 -0500] [51906] [CRITICAL] WORKER TIMEOUT (pid:51914)
[2016-12-07 21:34:15 -0500] [51906] [CRITICAL] WORKER TIMEOUT (pid:51915)
[2016-12-07 21:34:15 -0500] [51906] [CRITICAL] WORKER TIMEOUT (pid:51916)
[2016-12-07 21:34:15 -0500] [51906] [CRITICAL] WORKER TIMEOUT (pid:51917)
[2016-12-07 21:34:15 -0500] [51906] [CRITICAL] WORKER TIMEOUT (pid:51918)
[2016-12-07 21:34:15 -0500] [51906] [CRITICAL] WORKER TIMEOUT (pid:51919)
[2016-12-07 21:46:55 -0500] [51906] [CRITICAL] WORKER TIMEOUT (pid:51969)
[2016-12-07 21:46:55 -0500] [51906] [CRITICAL] WORKER TIMEOUT (pid:51970)
[2016-12-07 21:46:55 -0500] [51906] [CRITICAL] WORKER TIMEOUT (pid:51972)
[2016-12-07 21:46:55 -0500] [51906] [CRITICAL] WORKER TIMEOUT (pid:51975)
[2016-12-07 21:46:55 -0500] [51906] [CRITICAL] WORKER TIMEOUT (pid:51977)
[2016-12-07 22:38:16 -0500] [51906] [CRITICAL] WORKER TIMEOUT (pid:52000)
[2016-12-07 22:38:16 -0500] [51906] [CRITICAL] WORKER TIMEOUT (pid:51971)
[2016-12-07 22:38:16 -0500] [51906] [CRITICAL] WORKER TIMEOUT (pid:51973)
[2016-12-07 22:38:16 -0500] [51906] [CRITICAL] WORKER TIMEOUT (pid:51974)
[2016-12-07 22:38:16 -0500] [51906] [CRITICAL] WORKER TIMEOUT (pid:51976)
[2016-12-07 22:38:16 -0500] [51906] [CRITICAL] WORKER TIMEOUT (pid:51996)
[2016-12-07 22:38:16 -0500] [51906] [CRITICAL] WORKER TIMEOUT (pid:51997)
[2016-12-07 22:38:16 -0500] [51906] [CRITICAL] WORKER TIMEOUT (pid:51998)
[2016-12-07 22:38:16 -0500] [51906] [CRITICAL] WORKER TIMEOUT (pid:51999)
[2016-12-08 00:25:43 -0500] [51906] [CRITICAL] WORKER TIMEOUT (pid:52028)
[2016-12-08 12:40:05 -0500] [53524] [CRITICAL] WORKER TIMEOUT (pid:53528)
[2016-12-08 12:40:05 -0500] [53524] [CRITICAL] WORKER TIMEOUT (pid:53529)
[2016-12-08 12:40:05 -0500] [53524] [CRITICAL] WORKER TIMEOUT (pid:53530)
[2016-12-08 12:40:05 -0500] [53524] [CRITICAL] WORKER TIMEOUT (pid:53531)
[2016-12-08 12:40:05 -0500] [53524] [CRITICAL] WORKER TIMEOUT (pid:53532)
[2016-12-08 12:40:05 -0500] [53524] [CRITICAL] WORKER TIMEOUT (pid:53533)
[2016-12-08 12:40:07 -0500] [53524] [CRITICAL] WORKER TIMEOUT (pid:53536)
[2016-12-08 12:40:07 -0500] [53524] [CRITICAL] WORKER TIMEOUT (pid:53534)
[2016-12-08 12:40:07 -0500] [53524] [CRITICAL] WORKER TIMEOUT (pid:53535)
[2016-12-08 17:10:36 -0500] [53524] [CRITICAL] WORKER TIMEOUT (pid:53549)
[2016-12-08 17:10:36 -0500] [53524] [CRITICAL] WORKER TIMEOUT (pid:53550)
[2016-12-08 17:10:36 -0500] [53524] [CRITICAL] WORKER TIMEOUT (pid:53551)
[2016-12-08 17:10:36 -0500] [53524] [CRITICAL] WORKER TIMEOUT (pid:53552)
[2016-12-08 17:10:36 -0500] [53524] [CRITICAL] WORKER TIMEOUT (pid:53553)
[2016-12-08 17:10:36 -0500] [53524] [CRITICAL] WORKER TIMEOUT (pid:53557)
[2016-12-08 17:10:36 -0500] [53524] [CRITICAL] WORKER TIMEOUT (pid:53622)
[2016-12-08 17:10:36 -0500] [53524] [CRITICAL] WORKER TIMEOUT (pid:53623)
[2016-12-08 17:10:36 -0500] [53524] [CRITICAL] WORKER TIMEOUT (pid:53624)
[2016-12-08 17:58:01 -0500] [53524] [CRITICAL] WORKER TIMEOUT (pid:57073)
[2016-12-08 17:58:01 -0500] [53524] [CRITICAL] WORKER TIMEOUT (pid:57074)
[2016-12-08 17:58:01 -0500] [53524] [CRITICAL] WORKER TIMEOUT (pid:57075)
[2016-12-08 17:58:01 -0500] [53524] [CRITICAL] WORKER TIMEOUT (pid:57076)
[2016-12-08 17:58:01 -0500] [53524] [CRITICAL] WORKER TIMEOUT (pid:57077)
[2016-12-08 17:58:01 -0500] [53524] [CRITICAL] WORKER TIMEOUT (pid:57078)
[2016-12-08 17:58:01 -0500] [53524] [CRITICAL] WORKER TIMEOUT (pid:57079)
[2016-12-08 17:58:01 -0500] [53524] [CRITICAL] WORKER TIMEOUT (pid:57080)
[2016-12-08 17:58:01 -0500] [53524] [CRITICAL] WORKER TIMEOUT (pid:57081)
[2016-12-09 13:09:17 -0500] [60775] [CRITICAL] WORKER TIMEOUT (pid:60779)
[2016-12-09 13:09:17 -0500] [60775] [CRITICAL] WORKER TIMEOUT (pid:60780)
[2016-12-09 13:09:17 -0500] [60775] [CRITICAL] WORKER TIMEOUT (pid:60781)
[2016-12-09 13:09:17 -0500] [60775] [CRITICAL] WORKER TIMEOUT (pid:60782)
[2016-12-09 13:09:17 -0500] [60775] [CRITICAL] WORKER TIMEOUT (pid:60783)
[2016-12-09 13:09:17 -0500] [60775] [CRITICAL] WORKER TIMEOUT (pid:60784)
[2016-12-09 13:09:17 -0500] [60775] [CRITICAL] WORKER TIMEOUT (pid:60785)
[2016-12-09 13:09:17 -0500] [60775] [CRITICAL] WORKER TIMEOUT (pid:60786)
[2016-12-09 13:09:17 -0500] [60775] [CRITICAL] WORKER TIMEOUT (pid:60787)
[2016-12-09 13:29:15 -0500] [61782] [CRITICAL] WORKER TIMEOUT (pid:61786)
[2016-12-09 13:29:15 -0500] [61782] [CRITICAL] WORKER TIMEOUT (pid:61787)
[2016-12-09 13:29:15 -0500] [61782] [CRITICAL] WORKER TIMEOUT (pid:61788)
[2016-12-09 13:29:16 -0500] [61782] [CRITICAL] WORKER TIMEOUT (pid:61792)
[2016-12-09 13:29:16 -0500] [61782] [CRITICAL] WORKER TIMEOUT (pid:61793)
[2016-12-09 13:29:16 -0500] [61782] [CRITICAL] WORKER TIMEOUT (pid:61794)
[2016-12-09 13:29:16 -0500] [61782] [CRITICAL] WORKER TIMEOUT (pid:61789)
[2016-12-09 13:29:16 -0500] [61782] [CRITICAL] WORKER TIMEOUT (pid:61790)
[2016-12-09 13:29:16 -0500] [61782] [CRITICAL] WORKER TIMEOUT (pid:61791)
[2016-12-09 13:29:46 -0500] [61782] [CRITICAL] WORKER TIMEOUT (pid:61803)
[2016-12-09 13:29:46 -0500] [61782] [CRITICAL] WORKER TIMEOUT (pid:61804)
[2016-12-09 13:29:46 -0500] [61782] [CRITICAL] WORKER TIMEOUT (pid:61805)
[2016-12-09 13:29:46 -0500] [61782] [CRITICAL] WORKER TIMEOUT (pid:61806)
[2016-12-09 13:29:46 -0500] [61782] [CRITICAL] WORKER TIMEOUT (pid:61807)
[2016-12-09 13:29:46 -0500] [61782] [CRITICAL] WORKER TIMEOUT (pid:61808)
[2016-12-09 13:29:46 -0500] [61782] [CRITICAL] WORKER TIMEOUT (pid:61809)
[2016-12-09 13:29:46 -0500] [61782] [CRITICAL] WORKER TIMEOUT (pid:61810)
[2016-12-09 13:29:46 -0500] [61782] [CRITICAL] WORKER TIMEOUT (pid:61811)
[2016-12-09 13:30:17 -0500] [61782] [CRITICAL] WORKER TIMEOUT (pid:61824)
[2016-12-09 13:30:17 -0500] [61782] [CRITICAL] WORKER TIMEOUT (pid:61825)
[2016-12-09 13:30:17 -0500] [61782] [CRITICAL] WORKER TIMEOUT (pid:61826)
[2016-12-09 13:30:17 -0500] [61782] [CRITICAL] WORKER TIMEOUT (pid:61827)
[2016-12-09 13:30:17 -0500] [61782] [CRITICAL] WORKER TIMEOUT (pid:61828)
[2016-12-09 13:30:17 -0500] [61782] [CRITICAL] WORKER TIMEOUT (pid:61820)
[2016-12-09 13:30:17 -0500] [61782] [CRITICAL] WORKER TIMEOUT (pid:61821)
[2016-12-09 13:30:17 -0500] [61782] [CRITICAL] WORKER TIMEOUT (pid:61822)
[2016-12-09 13:30:17 -0500] [61782] [CRITICAL] WORKER TIMEOUT (pid:61823)
